Workbook

Sheet 01_Seleccion_Tecnicas
A1: ID_Tecnica_Interna | B1: Táctica_MITRE | C1: ID_Táctica | D1: Técnica_MITRE | E1: ID_Técnica | F1: Subtécnica | G1: ID_Subtécnica | H1: Descripción | I1: Justificación_selección | J1: Observable_en_HOST | K1: Tipo_de_Evidencia_Host_Esperada | L1: Procedimiento_de_Prueba | M1: Criterio_de_Éxito | N1: Notas_Tecnicas | O1: Enlace_Referencia
A2: {="TEC-"&TEXT(ROW()-ROW(tblTecnicas[#Headers]),"000")} -> TEC-001 | B2: Execution | C2: TA0002 | D2: Command and Scripting Interpreter | E2: T1059 | F2: PowerShell | G2: T1059.001 | H2: Ejecución de comandos o scripts mediante PowerShell. | I2: Muy frecuente, muy visible en host y perfecta para una primera prueba. | J2: Sí | K2: Process Create | L2: Ejecutar powershell.exe con un script benigno local y parámetros visibles. | M2: Ver powershell.exe con Image, ParentImage y CommandLine coherentes. | N2: Empezar sin ofuscación; luego hacer una variante con argumentos más sospechosos. | O2: https://attack.mitre.org/techniques/T1059/001/
A3: {="TEC-"&TEXT(ROW()-ROW(tblTecnicas[#Headers]),"000")} -> TEC-002 | B3: Execution | C3: TA0002 | D3: Command and Scripting Interpreter | E3: T1059 | F3: Windows Command Shell | G3: T1059.003 | H3: Ejecución de comandos a través de cmd.exe. | I3: Muy simple de probar y muy trazable. | J3: Sí | K3: Process Create | L3: Lanzar cmd.exe con comandos benignos de prueba. | M3: Ver cmd.exe y su línea de comandos completa. | N3: Buena como baseline antes de PowerShell más complejo. | O3: https://attack.mitre.org/techniques/T1059/003
A4: {="TEC-"&TEXT(ROW()-ROW(tblTecnicas[#Headers]),"000")} -> TEC-003 | B4: Persistence | C4: TA0003 | D4: Scheduled Task/Job | E4: T1053 | F4: Scheduled Task | G4: T1053.005 | H4: Creación de una tarea programada para ejecutar un binario o script. | I4: Muy típica y fácil de reproducir de forma benigna. | J4: Sí | K4: Process Create | L4: Crear una tarea programada que ejecute una acción benigna y forzar su ejecución. | M4: Ver schtasks.exe y posteriormente el proceso lanzado por la tarea. | N4: Técnica multiuso; aquí la modelas como persistencia. | O4: https://attack.mitre.org/techniques/T1053/005
A5: {="TEC-"&TEXT(ROW()-ROW(tblTecnicas[#Headers]),"000")} -> TEC-004 | B5: Persistence | C5: TA0003 | D5: Boot or Logon Autostart Execution | E5: T1547 | F5: Registry Run Keys / Startup Folder - HKCU Run | G5: T1547.001 | H5: Persistencia mediante clave Run o carpeta de inicio. | I5: Clásica, muy justificable y con evidencia clara en registro. | J5: Sí | K5: Regisitry | L5: Crear una clave Run de prueba o usar Startup con un payload benigno. | M5: Ver evento de modificación de registro y, si aplica, la ejecución posterior al logon. | N5: Empezar por HKCU, no por HKLM. | O5: https://attack.mitre.org/techniques/T1547/001
A6: {="TEC-"&TEXT(ROW()-ROW(tblTecnicas[#Headers]),"000")} -> TEC-005 | B6: Execution | C6: TA0002 | D6: System Services | E6: T1569 | F6: Service Execution | G6: T1569.002 | H6: Ejecución de contenido a través de un servicio de Windows. | I6: Muy representativa y bastante simple. | J6: Sí | K6: Service | L6: Crear o modificar un servicio benigno y arrancarlo. | M6: Ver creación/modificación y arranque del servicio, además del proceso hijo. | N6: Mejor usar un servicio temporal de prueba y borrarlo al final. | O6: https://attack.mitre.org/techniques/T1569/002
A7: {="TEC-"&TEXT(ROW()-ROW(tblTecnicas[#Headers]),"000")} -> TEC-006 | B7: Discovery | C7: TA0007 | D7: Software Discovery | E7: T1518 | F7: Security Software Discovery | G7: T1518.001 | H7: Enumeración de software de seguridad o herramientas defensivas instaladas. | I7: Muy relevante antes de evasión y muy asumible en primeras pruebas. | J7: Sí | K7: Process Create | L7: Ejecutar una consulta benigna para listar AV, EDR o sensores instalados. | M7: Ver el proceso de consulta y su línea de comandos. | N7: Aquí solo discovery, sin desactivar nada. | O7: https://attack.mitre.org/techniques/T1518/001
A8: {="TEC-"&TEXT(ROW()-ROW(tblTecnicas[#Headers]),"000")} -> TEC-007 | B8: Impact | C8: TA0040 | D8: Data Encrypted for Impact | E8: T1486 | F8: N/A | G8: N/A | H8: Cifrado de ficheros para interrumpir la disponibilidad de la información. | I8: Técnica núcleo del foco ransomware del TFM. | J8: Sí | K8: Multiple | L8: Usar un simulador benigno que cifre o renombre solo archivos dummy en una carpeta de laboratorio. | M8: Ver el proceso lanzado y actividad anómala concentrada sobre la carpeta de prueba. | N8: Siempre con snapshot previo; nunca sobre datos reales. | O8: https://attack.mitre.org/techniques/T1486/

Sheet 02_Operaciones_Benignas
A1: ID_Operación_Benigna | B1: Operación benigna | C1: Descripción | D1: Justificación_selección | E1: Observable_en_HOST | F1: Tipo_de_Evidencia_Host_Esperada | G1: Procedimiento_de_Prueba | H1: Criterio_de_Éxito | I1: Notas_Tecnicas | J1: Código_usado
A2: {="OB-"&TEXT(ROW()-ROW(tblTecnicas[#Headers]),"000")} -> OB-001 | B2: PowerShell administrativo básico | C2: Ejecución de PowerShell para consultar fecha y procesos, sin flags sospechosos ni marcadores TFM/TEC. | D2: Permite comprobar que el artifact no alerta por cualquier ejecución legítima de PowerShell. | E2: Sí: powershell.exe | F2: Sysmon Event ID 1 - ProcessCreation | G2: Ejecutar PowerShell con una consulta administrativa básica. | H2: La operación genera telemetría host, pero no alerta CU-TFM-001. | I2: Caso benigno de referencia para diferenciar uso administrativo de PowerShell frente a ejecución sospechosa con bypass, encodedcommand o marcadores de laboratorio. | J2: powershell.exe -Command "Get-Date; Get-Process | Select-Object -First 5"
A3: OB-002 | B3: PowerShell con consulta de sistema | C3: Consulta información básica del sistema operativo mediante Get-CimInstance. | D3: Permite validar que una consulta WMI/CIM genérica no se confunde con descubrimiento de software de seguridad. | E3: Sí: powershell.exe | F3: Sysmon Event ID 1 - ProcessCreation | G3: Ejecutar una consulta CIM sobre Win32_OperatingSystem. | H3: No debe generar alerta CU-TFM-006. | I3: Tras el ajuste, TEC-006 solo debe alertar si aparece SecurityCenter2 o AntivirusProduct. | J3: powershell.exe -Command "Get-CimInstance Win32_OperatingSystem | Select-Object Caption,Version"
A4: OB-003 | B4: CMD benigno simple | C4: Ejecución de cmd.exe /c para crear un fichero de texto sin marcadores TEC. | D4: Valida que no se alerta cualquier uso de cmd.exe. | E4: Sí: cmd.exe | F4: Sysmon Event ID 1 - ProcessCreation; posible Event ID 11 - FileCreate | G4: Crear un fichero benigno en C:\Users\Public. | H4: No debe generar alerta CU-TFM-002. | I4: No incluye TFM_CMD_TEST, TEC002_OK ni otros marcadores de laboratorio. | J4: cmd.exe /c echo prueba benigna > C:\Users\Public\benigno_cmd.txt
A5: OB-004 | B5: Consulta de directorio con CMD | C5: Listado de archivos mediante dir. | D5: Representa una operación normal de usuario o administración básica. | E5: Sí: cmd.exe | F5: Sysmon Event ID 1 - ProcessCreation | G5: Ejecutar un listado de directorio sobre C:\Users\Public. | H5: No debe generar alerta CU-TFM-002. | I5: Comprueba que el uso de cmd.exe /c por sí solo no dispara la regla. | J5: cmd.exe /c dir C:\Users\Public
A6: OB-005 | B6: Consulta de tareas programadas | C6: Enumeración de tareas existentes mediante schtasks /query. | D6: Distingue consulta legítima de creación o manipulación de tareas programadas. | E6: Sí: schtasks.exe | F6: Sysmon Event ID 1 - ProcessCreation | G6: Ejecutar una consulta de tareas programadas. | H6: No debe generar alerta CU-TFM-003. | I6: La consulta pasiva no representa ejecución ni persistencia. | J6: schtasks /query /fo LIST
A7: OB-006 | B7: Creación de tarea programada benigna | C7: Crea y elimina una tarea programada benigna sin marcadores TFM. | D7: Prueba actividad dual-use real: puede ser administración legítima o persistencia maliciosa. | E7: Sí: schtasks.exe | F7: Sysmon Event ID 1 - ProcessCreation | G7: Crear y eliminar una tarea programada benigna. | H7: Puede generar alerta CU-TFM-003; si alerta, se clasifica como falso positivo controlado o dual-use esperable. | I7: Se mantiene como detección amplia porque schtasks /create y /delete son relevantes en contexto SOC. | J7: schtasks /create /tn "Benign_Update_Check" /tr "cmd.exe /c echo benigno > C:\Users\Public\benign_task.txt" /sc once /st 23:59 && schtasks /delete /tn "Benign_Update_Check" /f
A8: OB-007 | B8: Consulta de Run Keys | C8: Consulta pasiva de claves Run del registro sin modificación. | D8: Diferencia enumeración legítima de persistencia mediante modificación de Run Keys. | E8: Sí: reg.exe | F8: Sysmon Event ID 1 - ProcessCreation | G8: Ejecutar reg query sobre HKCU\Software\Microsoft\Windows\CurrentVersion\Run. | H8: No debe generar alerta CU-TFM-004. | I8: Tras el ajuste, TEC-004 debe alertar solo ante add/delete, no ante query. | J8: reg query "HKCU\Software\Microsoft\Windows\CurrentVersion\Run"
A9: OB-008 | B9: Modificación benigna de clave no persistente | C9: Crea y elimina una clave de registro no relacionada con Run. | D9: Comprueba que la regla de persistencia no detecta cualquier modificación del registro. | E9: Sí: reg.exe | F9: Sysmon Event ID 1 - ProcessCreation | G9: Crear y eliminar una clave HKCU\Software\TFM_Benigno. | H9: No debe generar alerta CU-TFM-004. | I9: Aunque aparece TFM en la ruta, no afecta a CurrentVersion\Run, por lo que no debería mapear a T1547.001. | J9: reg add HKCU\Software\TFM_Benigno /v Test /t REG_SZ /d benigno /f && reg delete HKCU\Software\TFM_Benigno /f
A10: OB-009 | B10: Consulta de servicio Windows | C10: Consulta el estado de un servicio legítimo del sistema. | D10: Valida que no se detecta cualquier uso de sc.exe. | E10: Sí: sc.exe | F10: Sysmon Event ID 1 - ProcessCreation | G10: Ejecutar sc query sobre Spooler. | H10: No debe generar alerta CU-TFM-005. | I10: La consulta de servicio no implica creación ni ejecución de servicio. | J10: sc query Spooler
A11: OB-010 | B11: Consulta de servicio Windows Update | C11: Consulta el estado del servicio wuauserv sin modificarlo. | D11: Comprueba que operaciones administrativas pasivas sobre servicios no se clasifican como T1569.002. | E11: Sí: sc.exe | F11: Sysmon Event ID 1 - ProcessCreation | G11: Ejecutar sc query sobre wuauserv. | H11: No debe generar alerta CU-TFM-005. | I11: Se evita parar o arrancar servicios para no alterar el sistema. | J11: sc query wuauserv
A12: OB-011 | B12: Consulta WMI no sensible | C12: Consulta WMI genérica sobre el sistema operativo mediante wmic. | D12: Diferencia WMI administrativo de descubrimiento de antivirus o software de seguridad. | E12: Sí: wmic.exe | F12: Sysmon Event ID 1 - ProcessCreation | G12: Ejecutar wmic os get Caption,Version. | H12: No debe generar alerta CU-TFM-006. | I12: Tras el ajuste, TEC-006 debe requerir SecurityCenter2 o AntivirusProduct. | J12: wmic os get Caption,Version
A13: OB-012 | B13: Creación de archivos .txt | C13: Crea varios ficheros de texto no cifrados. | D13: Distingue actividad normal de escritura de archivos frente a creación de artefactos cifrados tipo ransomware. | E13: Sí: cmd.exe; creación de .txt | F13: Sysmon Event ID 1 - ProcessCreation; posible Event ID 11 - FileCreate | G13: Crear una carpeta y varios archivos .txt en C:\Users\Public. | H13: No debe generar alerta CU-TFM-007. | I13: No se usa extensión .aes ni rutas TEC-007_LAB/Ransomware. | J13: cmd.exe /c mkdir C:\Users\Public\benign_files & echo test > C:\Users\Public\benign_files\file1.txt & echo test > C:\Users\Public\benign_files\file2.txt
A14: OB-013 | B14: Copia de archivos | C14: Copia un fichero benigno a una carpeta de respaldo no asociada al laboratorio ransomware. | D14: Simula una operación normal de usuario o backup sin cifrado ni extensión sospechosa. | E14: Sí: cmd.exe; copy; creación en destino | F14: Sysmon Event ID 1 - ProcessCreation; posible Event ID 11 - FileCreate | G14: Copiar file1.txt a una carpeta benign_backup. | H14: No debe generar alerta CU-TFM-007. | I14: Evita rutas Ransomware, TEC-007_LAB y extensión .aes para medir falsos positivos. | J14: cmd.exe /c mkdir C:\Users\Public\benign_backup & copy C:\Users\Public\benign_files\file1.txt C:\Users\Public\benign_backup\file1_copy.txt
... A16: OB-015 | B16: Creación de archivo con extensión no .aes | C16: Crea un archivo .bak benigno. | D16: Verifica que la detección no alerta por cualquier extensión distinta a .txt. | E16: Sí: cmd.exe; creación de .bak | F16: Sysmon Event ID 1 - ProcessCreation; posible Event ID 11 - FileCreate | G16: Crear un archivo file1.bak en carpeta benigna. | H16: No debe generar alerta CU-TFM-007. | I16: Valida que la regla ransomware se centra en .aes y marcadores/rutas controladas. | J16: cmd.exe /c echo backup > C:\Users\Public\benign_files\file1.bak

Sheet 03_Evaluacion_VR
A1: ID_Prueba | B1: ID_Interna | C1: Evidencia_Host_Observada | D1: Escenario_Prueba | E1: VM_Snapshot_ID | F1: Version_Velociraptor | G1: Artefacto_VR_Usado | H1: Tipo_Artefacto | I1: Modo_Ejecución | J1: Resultado_Detección | K1: Ground_Truth | L1: Clasificacion_Resultado | M1: Resumen_Evidencia | N1: Tiempo_Hasta_Evidencia | O1: Replicable | P1: Ref_Captura_Log_Anexo | Q1: Fuente_Telemetria_Host | R1: Deteccion_VR_OK | S1: Comentario
A2: ="PR-"&TEXT(ROW()-1,"000") -> PR-001 | B2: TEC-001 | C2: EventID 1 (Process Create) con Image = powershell.exe, CommandLine = powershell.exe -NoProfile -ExecutionPolicy Bypass -File prueba_ps.ps1 y ParentImage = cmd.exe | D2: Ejecución controlada de script benigno local mediante PowerShell | E2: 02_VR_Con_Artifacts_Funcionando | F2: 0.75.6 | G2: Custom.TFM.Alert.Process/Sysmon_Process_File_UseCases | H2: Event artifact | I2: Client Event | J2: Detectado | K2: Positivo | L2: verdadero positivo | M2: Velociraptor mostró un evento Sysmon del canal Microsoft-Windows-Sysmon/Operational con EventID = 1, donde se observó la ejecución de powershell.exe, su línea de comandos y el proceso padre cmd.exe | N2: <5 min | O2: Sí | P2: Resultado_TEC-001.png | Q2: Windows.EventLogs.Evtx | R2: Sí | S2: La detección es válida, pero en este artifact la información útil aparece embebida en Message, no en columnas separadas
A3: ="PR-"&TEXT(ROW()-1,"000") -> PR-002 | B3: TEC-002 | C3: Proceso cmd.exe con CommandLine conteniendo el marcador TEC002_OK; ParentCommandLine asociado a C:\Windows\Explorer.EXE; aparición coherente de procesos hijo como conhost.exe y timeout.exe. | D3: Ejecución benigna controlada de cmd.exe para crear un fichero temporal mediante echo, incluyendo una variante con timeout para mejorar la observabilidad. | E3: 02_VR_Con_Artifacts_Funcionando | F3: 0.75.6 | G3: Custom.TFM.Alert.Process/Sysmon_Process_File_UseCases | H3: Event artifact | I3: Client Event | J3: Detectado | K3: Positivo | L3: verdadero positivo | M3: Velociraptor registró cmd.exe con la línea de comandos de la prueba y el marcador TEC002_OK, con relación padre-hijo coherente respecto a explorer.exe. | N3: <5 min | O3: Sí | P3: Resultado_TEC-002.png | Q3: Sysmon Event ID 1 — Process Create | R3: Sí | S3: La variante con timeout fue más robusta que la ejecución demasiado corta. Resultado válido como prueba base de ejecución vía shell.
A4: ="PR-"&TEXT(ROW()-1,"000") -> PR-003 | B4: TEC-003 | C4: Creación de tarea programada TFM-TEC-003, ejecución de schtasks.exe, ejecución de cmd.exe y creación de C:\Users\Public\tec003_ok.txt | D4: Creación manual de tarea programada benigna y ejecución forzada con schtasks /run | E4: 03_TFM_Montado_Configurado | F4: 0.75.6 | G4: Custom.TFM.Alert.Process/Sysmon_Process_File_UseCases | H4: Event artifact | I4: Client Event | J4: Detectado | K4: Positivo | L4: verdadero positivo | M4: Se creó la tarea TFM-TEC-003, se ejecutó manualmente y se generó correctamente el fichero de evidencia | N4: <5 min | O4: Sí | P4: Resultado_TEC-003.png | Q4: Sysmon Event ID 1 — Process Create | R4: Sí | S4: Técnica validada correctamente; la ejecución final funcionó al usar comando directo en la tarea programada
A5: ="PR-"&TEXT(ROW()-1,"000") -> PR-004 | B5: TEC-004 | C5: Clave HKCU\Software\Microsoft\Windows\CurrentVersion\Run con valor TFM_T1547_001_test → C:\Windows\System32\calc.exe; procesos reg.exe (add/delete) y ejecución de calc.exe tras logon. | D5: VM Windows 10 aislada; usuario estándar seguridad; script batch TFM_T1547_001.bat que crea y elimina persistencia T1547.001 apuntando a calc.exe. | E5: 04_Antes_de_persistencia | F5: 0.75.6 | G5: Custom.TFM.Alert.Process/Sysmon_Process_File_UseCases | H5: Event artifact | I5: Client Event | J5: Detectado | K5: Positivo | L5: verdadero positivo | M5: Eventos de reg.exe con reg add/delete HKCU\...\Run TFM_T1547_001_test invocados desde cmd.exe (parent Explorer.EXE); presencia temporal del valor Run en StartupItems. | N5: <5 min | O5: Sí | P5: Resultado_TEC-004.png | Q5: Lectura del registro de usuario (HKCU Run). | R5: Sí | S5: Caso de bajo riesgo usando binario legítimo (calc.exe) como payload benigno; escenario ideal para ilustrar T1547.001 con alta trazabilidad y limpieza sencilla en entorno académico.
A6: ="PR-"&TEXT(ROW()-1,"000") -> PR-005 | B6: TEC-005 | C6: Creacion de servicio temporal TFM_TEC005_20260406_151223 con binPath C:\Windows\System32\cmd.exe /c echo ServicioEjecutado_20260406_151223 > "C:\Users\seguridad\Desktop\TFM\Pruebas\TEC005\TFM_TEC005_20260406_151223.txt"; generacion correcta del fichero de evidencia y posterior borrado del servicio. | D6: VM Windows 10 aislada; usuario seguridad; PowerShell como administrador; script sc.ps1 que crea, arranca, verifica y elimina un servicio temporal benigno para T1569.002. | E6: 04_Antes_de_persistencia | F6: 0.75.6 | G6: Custom.TFM.Alert.Process/Sysmon_Process_File_UseCases | H6: Event artifact | I6: Client Event | J6: Detectado | K6: Positivo | L6: verdadero positivo | M6: Evento 7045 capturado en Velociraptor con nombre de servicio TFM_TEC005_20260406_151223, DisplayName TFM TEC005 Test Service e ImagePath apuntando a cmd.exe /c echo ServicioEjecutado_20260406_151223 > "...TFM_TEC005_20260406_151223.txt"; evidencia host generada correctamente y limpieza final del servicio completada. | N6: <5 min | O6: Sí | P6: Resultado_TEC-005.png & Resultado_TEC-005.2.png | Q6: Log System / Service Control Manager (7045) y evidencia host en fichero de salida. | R6: Sí | S6: Caso benigno, trazable y de bajo riesgo para ilustrar T1569.002 mediante creacion y ejecucion de un servicio temporal; alta claridad forense y limpieza sencilla para entorno academico.
A7: ="PR-"&TEXT(ROW()-1,"000") -> PR-006 | B7: TEC-006 | C7: Ejecución de powershell.exe con -File TEC006.ps1, powershell.exe con Get-CimInstance -Namespace 'root/SecurityCenter2' -ClassName 'AntivirusProduct', cmd.exe y WMIC.exe con consulta wmic /namespace:\\root\SecurityCenter2 path AntivirusProduct get displayName,productState | D7: VM Windows 10 aislada; usuario seguridad; PowerShell como administrador; script sc.ps1 que crea, arranca, verifica y elimina un servicio temporal benigno para T1569.002. | E7: 05_Despues_de_ransom | F7: 0.75.6 | G7: Custom.TFM.Alert.Process/Sysmon_Process_File_UseCases | H7: Event artifact | I7: Client Event | J7: Detectado | K7: Positivo | L7: verdadero positivo | M7: Sysmon Event ID 1 con CommandLine completa de TEC006.ps1, Get-CimInstance y WMIC sobre SecurityCenter2/AntivirusProduct; cadena powershell → cmd → WMIC | N7: <5 min | O7: Sí | P7: Resultado_TEC-006.png & Resultado_TEC-006.2.png | Q7: Sysmon Operational / Event ID 1 | R7: Sí | S7: Se descarta Windows.Events.ProcessCreation como evidencia principal por menor claridad; SysmonLogForward ofrece trazabilidad más sólida
A8: ="PR-"&TEXT(ROW()-1,"000") -> PR-007 | B8: TEC-007 | C8: Ejecución de powershell.exe con Scriptransom.ps1 (Sysmon ID 1), creación/escritura de artefactos asociados al ataque (Sysmon ID 11), presencia final de archivos .aes en TEC-007_LAB, presencia de copias en backups y ausencia final de temp_*.aes. No se observaron eventos ID 23/26 de borrado. | D8: Simulación controlada de cifrado AES sobre ficheros dummy, con copia previa a backups, borrado del original y movimiento interno del temporal cifrado a .aes final. | E8: 05_Despues_de_ransom | F8: 0.75.6 | G8: Custom.TFM.Alert.Process/Sysmon_Process_File_UseCases | H8: Event artifact | I8: Client Event | J8: Detectado | K8: Positivo | L8: verdadero positivo | M8: Velociraptor detectó la ejecución del script mediante Sysmon ID 1 y mostró eventos ID 11 coherentes con creación/escritura de artefactos del ataque. El estado final del host confirmó la presencia de .aes en la carpeta atacada y de backups del original. | N8: <5 min | O8: Sí | P8: Resultado_TEC-007.png & Resultado_TEC-007.2.png & Resultado_TEC-007.3.png & Resultado_TEC-007.4.png & Resultado_TEC-007.5.png & Resultado_TEC-007.6.png & Resultado_TEC-007.7.png | Q8: Sysmon (Microsoft-Windows-Sysmon/Operational) + estado del sistema de ficheros mediante glob() | R8: Sí | S8: Detección parcial-fuerte. Se demuestra ejecución e impacto final compatibles con T1486, pero no se observaron eventos FileDelete (ID 23/26) en la configuración activa de Sysmon. El paso temp_*.aes -> *.aes final se interpreta como move/rename interno inferido, no como evento explícito.
A9: ="PR-"&TEXT(ROW()-1,"000") -> PR-008 | B9: OB-001 | C9: Sysmon Event ID 1 asociado a powershell.exe con CommandLine = powershell.exe -Command "Get-Date; Get-Process | Select-Object -First 5" y ParentImage = cmd.exe. | D9: Validación de operaciones benignas para evaluación de falsos positivos del artifact | E9: 06_Validacion_FP_Artifact_Ajustado | F9: 0.75.6 | G9: Custom.TFM.Alert.Process/Sysmon_Process_File_UseCases | H9: Event artifact | I9: Client Event | J9: No detectado | K9: Negativo | L9: verdadero negativo | M9: La operación generó telemetría host normal de creación de proceso, pero el artifact no la clasificó como TEC-001 al no existir flags sospechosos ni marcadores TFM/TEC. | N9: No aplica | O9: Sí | P9: Resultado_OB-001.png | Q9: Sysmon Operational / Event ID 1 | R9: Sí | S9: Resultado correcto: PowerShell legítimo no fue alertado. Control benigno para TEC-001.
A10: ="PR-"&TEXT(ROW()-1,"000") -> PR-009 | B10: OB-002 | C10: Sysmon Event ID 1 asociado a powershell.exe con CommandLine = powershell.exe -Command "Get-CimInstance Win32_OperatingSystem | Select-Object Caption,Version". | D10: Validación de operaciones benignas para evaluación de falsos positivos del artifact | E10: 06_Validacion_FP_Artifact_Ajustado | F10: 0.75.6 | G10: Custom.TFM.Alert.Process/Sysmon_Process_File_UseCases | H10: Event artifact | I10: Client Event | J10: No detectado | K10: Negativo | L10: verdadero negativo | M10: La consulta CIM/WMI genérica del sistema operativo generó telemetría host, pero no fue clasificada como TEC-006 tras restringir la regla a SecurityCenter2/AntivirusProduct. | N10: No aplica | O10: Sí | P10: Resultado_OB-002.png | Q10: Sysmon Operational / Event ID 1 | R10: Sí | S10: Resultado correcto: WMI/CIM administrativo no sensible no generó alerta de descubrimiento de software de seguridad.
A11: ="PR-"&TEXT(ROW()-1,"000") -> PR-010 | B11: OB-003 | C11: Sysmon Event ID 1 asociado a cmd.exe con CommandLine = cmd.exe /c echo prueba benigna > C:\Users\Public\benigno_cmd.txt. | D11: Validación de operaciones benignas para evaluación de falsos positivos del artifact | E11: 06_Validacion_FP_Artifact_Ajustado | F11: 0.75.6 | G11: Custom.TFM.Alert.Process/Sysmon_Process_File_UseCases | H11: Event artifact | I11: Client Event | J11: No detectado | K11: Negativo | L11: verdadero negativo | M11: La ejecución de cmd.exe creó un fichero de texto benigno sin marcadores TEC002_OK ni TFM_CMD_TEST, por lo que no se generó alerta TEC-002. | N11: No aplica | O11: Sí | P11: Resultado_OB-003.png | Q11: Sysmon Operational / Event ID 1; posible Event ID 11 | R11: Sí | S11: Resultado correcto: cmd.exe /c por sí solo no dispara la regla si no contiene marcadores de laboratorio.
A12: ="PR-"&TEXT(ROW()-1,"000") -> PR-011 | B12: OB-004 | C12: Sysmon Event ID 1 asociado a cmd.exe con CommandLine = cmd.exe /c dir C:\Users\Public. | D12: Validación de operaciones benignas para evaluación de falsos positivos del artifact | E12: 06_Validacion_FP_Artifact_Ajustado | F12: 0.75.6 | G12: Custom.TFM.Alert.Process/Sysmon_Process_File_UseCases | H12: Event artifact | I12: Client Event | J12: No detectado | K12: Negativo | L12: verdadero negativo | M12: El listado de directorio generó telemetría de proceso, pero no coincidió con los criterios de TEC-002. | N12: No aplica | O12: Sí | P12: Resultado_OB-004.png | Q12: Sysmon Operational / Event ID 1 | R12: Sí | S12: Resultado correcto: operación administrativa básica sin alerta.
A13: ="PR-"&TEXT(ROW()-1,"000") -> PR-012 | B13: OB-005 | C13: Sysmon Event ID 1 asociado a schtasks.exe con CommandLine = schtasks /query /fo LIST. | D13: Validación de operaciones benignas para evaluación de falsos positivos del artifact | E13: 06_Validacion_FP_Artifact_Ajustado | F13: 0.75.6 | G13: Custom.TFM.Alert.Process/Sysmon_Process_File_UseCases | H13: Event artifact | I13: Client Event | J13: No detectado | K13: Negativo | L13: verdadero negativo | M13: La enumeración pasiva de tareas programadas no generó alerta CU-TFM-003, al no implicar creación, ejecución ni eliminación de tarea. | N13: No aplica | O13: Sí | P13: Resultado_OB-005.png | Q13: Sysmon Operational / Event ID 1 | R13: Sí | S13: Resultado correcto: se diferencia consulta legítima de manipulación de tareas programadas.
... A23: ="PR-"&TEXT(ROW()-1,"000") -> PR-022 | B23: OB-015 | C23: Sysmon Event ID 1 asociado a cmd.exe y posible Event ID 11 por creación de file1.bak en C:\Users\Public\benign_files. | D23: Validación de operaciones benignas para evaluación de falsos positivos del artifact | E23: 06_Validacion_FP_Artifact_Ajustado | F23: 0.75.6 | G23: Custom.TFM.Alert.Process/Sysmon_Process_File_UseCases | H23: Event artifact | I23: Client Event | J23: No detectado | K23: Negativo | L23: verdadero negativo | M23: La creación de un archivo .bak no activó TEC-007, confirmando que la regla no alerta por cualquier extensión no común. | N23: No aplica | O23: Sí | P23: Resultado_OB-015.png | Q23: Sysmon Operational / Event ID 1; posible Event ID 11 | R23: Sí | S23: Resultado correcto: la detección ransomware se mantiene centrada en .aes, rutas controladas y marcadores específicos.
A24: ="PR-"&TEXT(ROW()-1,"000") -> PR-023
A25: ="PR-"&TEXT(ROW()-1,"000") -> PR-024
A26: ="PR-"&TEXT(ROW()-1,"000") -> PR-025
A27: ="PR-"&TEXT(ROW()-1,"000") -> PR-026
A28: ="PR-"&TEXT(ROW()-1,"000") -> PR-027
A29: ="PR-"&TEXT(ROW()-1,"000") -> PR-028
A30: ="PR-"&TEXT(ROW()-1,"000") -> PR-029
A31: ="PR-"&TEXT(ROW()-1,"000") -> PR-030
A32: ="PR-"&TEXT(ROW()-1,"000") -> PR-031
A33: ="PR-"&TEXT(ROW()-1,"000") -> PR-032
A34: ="PR-"&TEXT(ROW()-1,"000") -> PR-033
A35: ="PR-"&TEXT(ROW()-1,"000") -> PR-034
... A100: ="PR-"&TEXT(ROW()-1,"000") -> PR-099

Sheet 04_Resumen
A1: Resumen final de evaluación: técnicas MITRE + operaciones benignas
A3: Indicador | B3: Valor | C3: Interpretación | E3: Lectura técnica para la memoria
A4: Total de pruebas | B4: =COUNTA($A$21:$A$42) -> 22 | C4: TEC + OB evaluadas | E4: 1 | F4: La cobertura de detección sobre las siete técnicas TEC fue completa: VP = 7 y FN = 0.
A5: Técnicas TEC evaluadas | B5: =COUNTIF($C$21:$C$42,"TEC") -> 7 | C5: Pruebas positivas esperadas | E5: 2 | F5: Las operaciones benignas validan discriminación: 14/15 fueron verdaderos negativos.
A6: Operaciones benignas OB | B6: =COUNTIF($C$21:$C$42,"OB") -> 15 | C6: Pruebas negativas esperadas | E6: 3 | F6: El único falso positivo corresponde a OB-006, una creación/eliminación de tarea programada; se clasifica como dual-use controlado.
A7: Verdaderos positivos (VP) | B7: =SUM($M$21:$M$42) -> 7 | C7: Técnicas detectadas correctamente | E7: 4 | F7: La tasa de FP por operación benigna queda acotada y es coherente con un artifact SOC-style orientado a superficie de exposición.
A8: Verdaderos negativos (VN) | B8: =SUM($N$21:$N$42) -> 14 | C8: Operaciones benignas no alertadas
A9: Falsos positivos (FP) | B9: =SUM($O$21:$O$42) -> 1 | C9: OB que generaron alerta | E9: Reglas de clasificación usadas en la hoja
A10: Falsos negativos (FN) | B10: =SUM($P$21:$P$42) -> 0 | C10: TEC no detectadas | E10: VP | F10: Ground_Truth = Positivo y Resultado_Detección = Detectado.
A11: Tasa detección TEC | B11: =IF(B5=0,0,B7/B5) -> 1 | C11: VP / TEC | E11: FN | F11: Ground_Truth = Positivo y Resultado_Detección distinto de Detectado.
A12: Tasa FP OB | B12: =IF(B6=0,0,B9/B6) -> 0.066666667 | C12: FP / OB | E12: VN | F12: Ground_Truth = Negativo y Resultado_Detección distinto de Detectado.
A13: Exactitud global | B13: =IF(B4=0,0,(B7+B8)/B4) -> 0.95454545 | C13: (VP + VN) / Total | E13: FP | F13: Ground_Truth = Negativo y Resultado_Detección = Detectado.
A14: Alertas dual-use controladas | B14: =SUM($Q$21:$Q$42) -> 1 | C14: FP esperable por comportamiento dual-use | E14: Dual-use | F14: Clasificación o comentario contiene dual-use/controlado; se conserva como FP, pero se interpreta con contexto SOC.
A15: Exactitud operativa ajustada | B15: =IF(B4=0,0,(B7+B8+B14)/B4) -> 1 | C15: (VP + VN + dual-use) / Total
A20: ID_Prueba | B20: ID_Interna | C20: Tipo | D20: Grupo/Operación | E20: MITRE/Técnica | F20: Resultado_Detección | G20: Ground_Truth | H20: Clasificacion_Resultado | I20: Clase_Normalizada | J20: Detectado_Bin | K20: GroundTruth_Bin | L20: Correcto_Bin | M20: VP_Bin | N20: VN_Bin | O20: FP_Bin | P20: FN_Bin | Q20: DualUse_Bin | R20: Replicable | S20: Deteccion_VR_OK | T20: Ref_Captura | U20: Comentario_TFM
A21: ='03_Evaluacion_VR'!A2 -> PR-001 | B21: ='03_Evaluacion_VR'!B2 -> TEC-001 | C21: =IF(LEFT(B21,3)="TEC","TEC",IF(LEFT(B21,2)="OB","OB","")) -> TEC | D21: =IF(C21="TEC",INDEX('01_Seleccion_Tecnicas'!$B:$B,MATCH(B21,'01_Seleccion_Tecnicas'!$A:$A,0)),INDEX('02_Operaciones_Benignas'!$B:$B,MATCH(B21,'02_Operaciones_Benignas'!$A:$A,0))) -> Execution | E21: =IF(C21="TEC",INDEX('01_Seleccion_Tecnicas'!$G:$G,MATCH(B21,'01_Seleccion_Tecnicas'!$A:$A,0)),INDEX('02_Operaciones_Benignas'!$B:$B,MATCH(B21,'02_Operaciones_Benignas'!$A:$A,0))) -> T1059.001 | F21: ='03_Evaluacion_VR'!J2 -> Detectado | G21: ='03_Evaluacion_VR'!K2 -> Positivo | H21: ='03_Evaluacion_VR'!L2 -> verdadero positivo | I21: =IF(AND(G21="Positivo",F21="Detectado"),"VP",IF(AND(G21="Positivo",F21<>"Detectado"),"FN",IF(AND(G21="Negativo",F21="Detectado"),"FP",IF(AND(G21="Negativo",F21<>"Detectado"),"VN","NE")))) -> VP | J21: =IF(F21="Detectado",1,0) -> 1 | K21: =IF(G21="Positivo",1,0) -> 1 | L21: =IF(OR(I21="VP",I21="VN"),1,0) -> 1 | M21: =IF(I21="VP",1,0) -> 1 | N21: =IF(I21="VN",1,0) -> 0 | O21: =IF(I21="FP",1,0) -> 0 | P21: =IF(I21="FN",1,0) -> 0 | Q21: =IF(ISNUMBER(SEARCH("dual",LOWER(H21&" "&U21))),1,0) -> 0 | R21: ='03_Evaluacion_VR'!O2 -> Sí | S21: ='03_Evaluacion_VR'!R2 -> Sí | T21: ='03_Evaluacion_VR'!P2 -> Resultado_TEC-001.png | U21: ='03_Evaluacion_VR'!S2 -> La detección es válida, pero en este artifact la información útil aparece embebida en Message, no en columnas separadas
A22: ='03_Evaluacion_VR'!A3 -> PR-002 | B22: ='03_Evaluacion_VR'!B3 -> TEC-002 | C22: =IF(LEFT(B22,3)="TEC","TEC",IF(LEFT(B22,2)="OB","OB","")) -> TEC | D22: =IF(C22="TEC",INDEX('01_Seleccion_Tecnicas'!$B:$B,MATCH(B22,'01_Seleccion_Tecnicas'!$A:$A,0)),INDEX('02_Operaciones_Benignas'!$B:$B,MATCH(B22,'02_Operaciones_Benignas'!$A:$A,0))) -> Execution | E22: =IF(C22="TEC",INDEX('01_Seleccion_Tecnicas'!$G:$G,MATCH(B22,'01_Seleccion_Tecnicas'!$A:$A,0)),INDEX('02_Operaciones_Benignas'!$B:$B,MATCH(B22,'02_Operaciones_Benignas'!$A:$A,0))) -> T1059.003 | F22: ='03_Evaluacion_VR'!J3 -> Detectado | G22: ='03_Evaluacion_VR'!K3 -> Positivo | H22: ='03_Evaluacion_VR'!L3 -> verdadero positivo | I22: =IF(AND(G22="Positivo",F22="Detectado"),"VP",IF(AND(G22="Positivo",F22<>"Detectado"),"FN",IF(AND(G22="Negativo",F22="Detectado"),"FP",IF(AND(G22="Negativo",F22<>"Detectado"),"VN","NE")))) -> VP | J22: =IF(F22="Detectado",1,0) -> 1 | K22: =IF(G22="Positivo",1,0) -> 1 | L22: =IF(OR(I22="VP",I22="VN"),1,0) -> 1 | M22: =IF(I22="VP",1,0) -> 1 | N22: =IF(I22="VN",1,0) -> 0 | O22: =IF(I22="FP",1,0) -> 0 | P22: =IF(I22="FN",1,0) -> 0 | Q22: =IF(ISNUMBER(SEARCH("dual",LOWER(H22&" "&U22))),1,0) -> 0 | R22: ='03_Evaluacion_VR'!O3 -> Sí | S22: ='03_Evaluacion_VR'!R3 -> Sí | T22: ='03_Evaluacion_VR'!P3 -> Resultado_TEC-002.png | U22: ='03_Evaluacion_VR'!S3 -> La variante con timeout fue más robusta que la ejecución demasiado corta. Resultado válido como prueba base de ejecución vía shell.
A23: ='03_Evaluacion_VR'!A4 -> PR-003 | B23: ='03_Evaluacion_VR'!B4 -> TEC-003 | C23: =IF(LEFT(B23,3)="TEC","TEC",IF(LEFT(B23,2)="OB","OB","")) -> TEC | D23: =IF(C23="TEC",INDEX('01_Seleccion_Tecnicas'!$B:$B,MATCH(B23,'01_Seleccion_Tecnicas'!$A:$A,0)),INDEX('02_Operaciones_Benignas'!$B:$B,MATCH(B23,'02_Operaciones_Benignas'!$A:$A,0))) -> Persistence | E23: =IF(C23="TEC",INDEX('01_Seleccion_Tecnicas'!$G:$G,MATCH(B23,'01_Seleccion_Tecnicas'!$A:$A,0)),INDEX('02_Operaciones_Benignas'!$B:$B,MATCH(B23,'02_Operaciones_Benignas'!$A:$A,0))) -> T1053.005 | F23: ='03_Evaluacion_VR'!J4 -> Detectado | G23: ='03_Evaluacion_VR'!K4 -> Positivo | H23: ='03_Evaluacion_VR'!L4 -> verdadero positivo | I23: =IF(AND(G23="Positivo",F23="Detectado"),"VP",IF(AND(G23="Positivo",F23<>"Detectado"),"FN",IF(AND(G23="Negativo",F23="Detectado"),"FP",IF(AND(G23="Negativo",F23<>"Detectado"),"VN","NE")))) -> VP | J23: =IF(F23="Detectado",1,0) -> 1 | K23: =IF(G23="Positivo",1,0) -> 1 | L23: =IF(OR(I23="VP",I23="VN"),1,0) -> 1 | M23: =IF(I23="VP",1,0) -> 1 | N23: =IF(I23="VN",1,0) -> 0 | O23: =IF(I23="FP",1,0) -> 0 | P23: =IF(I23="FN",1,0) -> 0 | Q23: =IF(ISNUMBER(SEARCH("dual",LOWER(H23&" "&U23))),1,0) -> 0 | R23: ='03_Evaluacion_VR'!O4 -> Sí | S23: ='03_Evaluacion_VR'!R4 -> Sí | T23: ='03_Evaluacion_VR'!P4 -> Resultado_TEC-003.png | U23: ='03_Evaluacion_VR'!S4 -> Técnica validada correctamente; la ejecución final funcionó al usar comando directo en la tarea programada
A24: ='03_Evaluacion_VR'!A5 -> PR-004 | B24: ='03_Evaluacion_VR'!B5 -> TEC-004 | C24: =IF(LEFT(B24,3)="TEC","TEC",IF(LEFT(B24,2)="OB","OB","")) -> TEC | D24: =IF(C24="TEC",INDEX('01_Seleccion_Tecnicas'!$B:$B,MATCH(B24,'01_Seleccion_Tecnicas'!$A:$A,0)),INDEX('02_Operaciones_Benignas'!$B:$B,MATCH(B24,'02_Operaciones_Benignas'!$A:$A,0))) -> Persistence | E24: =IF(C24="TEC",INDEX('01_Seleccion_Tecnicas'!$G:$G,MATCH(B24,'01_Seleccion_Tecnicas'!$A:$A,0)),INDEX('02_Operaciones_Benignas'!$B:$B,MATCH(B24,'02_Operaciones_Benignas'!$A:$A,0))) -> T1547.001 | F24: ='03_Evaluacion_VR'!J5 -> Detectado | G24: ='03_Evaluacion_VR'!K5 -> Positivo | H24: ='03_Evaluacion_VR'!L5 -> verdadero positivo | I24: =IF(AND(G24="Positivo",F24="Detectado"),"VP",IF(AND(G24="Positivo",F24<>"Detectado"),"FN",IF(AND(G24="Negativo",F24="Detectado"),"FP",IF(AND(G24="Negativo",F24<>"Detectado"),"VN","NE")))) -> VP | J24: =IF(F24="Detectado",1,0) -> 1 | K24: =IF(G24="Positivo",1,0) -> 1 | L24: =IF(OR(I24="VP",I24="VN"),1,0) -> 1 | M24: =IF(I24="VP",1,0) -> 1 | N24: =IF(I24="VN",1,0) -> 0 | O24: =IF(I24="FP",1,0) -> 0 | P24: =IF(I24="FN",1,0) -> 0 | Q24: =IF(ISNUMBER(SEARCH("dual",LOWER(H24&" "&U24))),1,0) -> 0 | R24: ='03_Evaluacion_VR'!O5 -> Sí | S24: ='03_Evaluacion_VR'!R5 -> Sí | T24: ='03_Evaluacion_VR'!P5 -> Resultado_TEC-004.png | U24: ='03_Evaluacion_VR'!S5 -> Caso de bajo riesgo usando binario legítimo (calc.exe) como payload benigno; escenario ideal para ilustrar T1547.001 con alta trazabilidad y limpieza sencilla en entorno académico.
A25: ='03_Evaluacion_VR'!A6 -> PR-005 | B25: ='03_Evaluacion_VR'!B6 -> TEC-005 | C25: =IF(LEFT(B25,3)="TEC","TEC",IF(LEFT(B25,2)="OB","OB","")) -> TEC | D25: =IF(C25="TEC",INDEX('01_Seleccion_Tecnicas'!$B:$B,MATCH(B25,'01_Seleccion_Tecnicas'!$A:$A,0)),INDEX('02_Operaciones_Benignas'!$B:$B,MATCH(B25,'02_Operaciones_Benignas'!$A:$A,0))) -> Execution | E25: =IF(C25="TEC",INDEX('01_Seleccion_Tecnicas'!$G:$G,MATCH(B25,'01_Seleccion_Tecnicas'!$A:$A,0)),INDEX('02_Operaciones_Benignas'!$B:$B,MATCH(B25,'02_Operaciones_Benignas'!$A:$A,0))) -> T1569.002 | F25: ='03_Evaluacion_VR'!J6 -> Detectado | G25: ='03_Evaluacion_VR'!K6 -> Positivo | H25: ='03_Evaluacion_VR'!L6 -> verdadero positivo | I25: =IF(AND(G25="Positivo",F25="Detectado"),"VP",IF(AND(G25="Positivo",F25<>"Detectado"),"FN",IF(AND(G25="Negativo",F25="Detectado"),"FP",IF(AND(G25="Negativo",F25<>"Detectado"),"VN","NE")))) -> VP | J25: =IF(F25="Detectado",1,0) -> 1 | K25: =IF(G25="Positivo",1,0) -> 1 | L25: =IF(OR(I25="VP",I25="VN"),1,0) -> 1 | M25: =IF(I25="VP",1,0) -> 1 | N25: =IF(I25="VN",1,0) -> 0 | O25: =IF(I25="FP",1,0) -> 0 | P25: =IF(I25="FN",1,0) -> 0 | Q25: =IF(ISNUMBER(SEARCH("dual",LOWER(H25&" "&U25))),1,0) -> 0 | R25: ='03_Evaluacion_VR'!O6 -> Sí | S25: ='03_Evaluacion_VR'!R6 -> Sí | T25: ='03_Evaluacion_VR'!P6 -> Resultado_TEC-005.png & Resultado_TEC-005.2.png | U25: ='03_Evaluacion_VR'!S6 -> Caso benigno, trazable y de bajo riesgo para ilustrar T1569.002 mediante creacion y ejecucion de un servicio temporal; alta claridad forense y limpieza sencilla para entorno academico.
A26: ='03_Evaluacion_VR'!A7 -> PR-006 | B26: ='03_Evaluacion_VR'!B7 -> TEC-006 | C26: =IF(LEFT(B26,3)="TEC","TEC",IF(LEFT(B26,2)="OB","OB","")) -> TEC | D26: =IF(C26="TEC",INDEX('01_Seleccion_Tecnicas'!$B:$B,MATCH(B26,'01_Seleccion_Tecnicas'!$A:$A,0)),INDEX('02_Operaciones_Benignas'!$B:$B,MATCH(B26,'02_Operaciones_Benignas'!$A:$A,0))) -> Discovery | E26: =IF(C26="TEC",INDEX('01_Seleccion_Tecnicas'!$G:$G,MATCH(B26,'01_Seleccion_Tecnicas'!$A:$A,0)),INDEX('02_Operaciones_Benignas'!$B:$B,MATCH(B26,'02_Operaciones_Benignas'!$A:$A,0))) -> T1518.001 | F26: ='03_Evaluacion_VR'!J7 -> Detectado | G26: ='03_Evaluacion_VR'!K7 -> Positivo | H26: ='03_Evaluacion_VR'!L7 -> verdadero positivo | I26: =IF(AND(G26="Positivo",F26="Detectado"),"VP",IF(AND(G26="Positivo",F26<>"Detectado"),"FN",IF(AND(G26="Negativo",F26="Detectado"),"FP",IF(AND(G26="Negativo",F26<>"Detectado"),"VN","NE")))) -> VP | J26: =IF(F26="Detectado",1,0) -> 1 | K26: =IF(G26="Positivo",1,0) -> 1 | L26: =IF(OR(I26="VP",I26="VN"),1,0) -> 1 | M26: =IF(I26="VP",1,0) -> 1 | N26: =IF(I26="VN",1,0) -> 0 | O26: =IF(I26="FP",1,0) -> 0 | P26: =IF(I26="FN",1,0) -> 0 | Q26: =IF(ISNUMBER(SEARCH("dual",LOWER(H26&" "&U26))),1,0) -> 0 | R26: ='03_Evaluacion_VR'!O7 -> Sí | S26: ='03_Evaluacion_VR'!R7 -> Sí | T26: ='03_Evaluacion_VR'!P7 -> Resultado_TEC-006.png & Resultado_TEC-006.2.png | U26: ='03_Evaluacion_VR'!S7 -> Se descarta Windows.Events.ProcessCreation como evidencia principal por menor claridad; SysmonLogForward ofrece trazabilidad más sólida
A27: ='03_Evaluacion_VR'!A8 -> PR-007 | B27: ='03_Evaluacion_VR'!B8 -> TEC-007 | C27: =IF(LEFT(B27,3)="TEC","TEC",IF(LEFT(B27,2)="OB","OB","")) -> TEC | D27: =IF(C27="TEC",INDEX('01_Seleccion_Tecnicas'!$B:$B,MATCH(B27,'01_Seleccion_Tecnicas'!$A:$A,0)),INDEX('02_Operaciones_Benignas'!$B:$B,MATCH(B27,'02_Operaciones_Benignas'!$A:$A,0))) -> Impact | E27: =IF(C27="TEC",INDEX('01_Seleccion_Tecnicas'!$G:$G,MATCH(B27,'01_Seleccion_Tecnicas'!$A:$A,0)),INDEX('02_Operaciones_Benignas'!$B:$B,MATCH(B27,'02_Operaciones_Benignas'!$A:$A,0))) -> N/A | F27: ='03_Evaluacion_VR'!J8 -> Detectado | G27: ='03_Evaluacion_VR'!K8 -> Positivo | H27: ='03_Evaluacion_VR'!L8 -> verdadero positivo | I27: =IF(AND(G27="Positivo",F27="Detectado"),"VP",IF(AND(G27="Positivo",F27<>"Detectado"),"FN",IF(AND(G27="Negativo",F27="Detectado"),"FP",IF(AND(G27="Negativo",F27<>"Detectado"),"VN","NE")))) -> VP | J27: =IF(F27="Detectado",1,0) -> 1 | K27: =IF(G27="Positivo",1,0) -> 1 | L27: =IF(OR(I27="VP",I27="VN"),1,0) -> 1 | M27: =IF(I27="VP",1,0) -> 1 | N27: =IF(I27="VN",1,0) -> 0 | O27: =IF(I27="FP",1,0) -> 0 | P27: =IF(I27="FN",1,0) -> 0 | Q27: =IF(ISNUMBER(SEARCH("dual",LOWER(H27&" "&U27))),1,0) -> 0 | R27: ='03_Evaluacion_VR'!O8 -> Sí | S27: ='03_Evaluacion_VR'!R8 -> Sí | T27: ='03_Evaluacion_VR'!P8 -> Resultado_TEC-007.png & Resultado_TEC-007.2.png & Resultado_TEC-007.3.png & Resultado_TEC-007.4.png & Resultado_TEC-007.5.png & Resultado_TEC-007.6.png & Resultado_TEC-007.7.png | U27: ='03_Evaluacion_VR'!S8 -> Detección parcial-fuerte. Se demuestra ejecución e impacto final compatibles con T1486, pero no se observaron eventos FileDelete (ID 23/26) en la configuración activa de Sysmon. El paso temp_*.aes -> *.aes final se interpreta como move/rename interno inferido, no como evento explícito.
A28: ='03_Evaluacion_VR'!A9 -> PR-008 | B28: ='03_Evaluacion_VR'!B9 -> OB-001 | C28: =IF(LEFT(B28,3)="TEC","TEC",IF(LEFT(B28,2)="OB","OB","")) -> OB | D28: =IF(C28="TEC",INDEX('01_Seleccion_Tecnicas'!$B:$B,MATCH(B28,'01_Seleccion_Tecnicas'!$A:$A,0)),INDEX('02_Operaciones_Benignas'!$B:$B,MATCH(B28,'02_Operaciones_Benignas'!$A:$A,0))) -> PowerShell administrativo básico | E28: =IF(C28="TEC",INDEX('01_Seleccion_Tecnicas'!$G:$G,MATCH(B28,'01_Seleccion_Tecnicas'!$A:$A,0)),INDEX('02_Operaciones_Benignas'!$B:$B,MATCH(B28,'02_Operaciones_Benignas'!$A:$A,0))) -> PowerShell administrativo básico | F28: ='03_Evaluacion_VR'!J9 -> No detectado | G28: ='03_Evaluacion_VR'!K9 -> Negativo | H28: ='03_Evaluacion_VR'!L9 -> verdadero negativo | I28: =IF(AND(G28="Positivo",F28="Detectado"),"VP",IF(AND(G28="Positivo",F28<>"Detectado"),"FN",IF(AND(G28="Negativo",F28="Detectado"),"FP",IF(AND(G28="Negativo",F28<>"Detectado"),"VN","NE")))) -> VN | J28: =IF(F28="Detectado",1,0) -> 0 | K28: =IF(G28="Positivo",1,0) -> 0 | L28: =IF(OR(I28="VP",I28="VN"),1,0) -> 1 | M28: =IF(I28="VP",1,0) -> 0 | N28: =IF(I28="VN",1,0) -> 1 | O28: =IF(I28="FP",1,0) -> 0 | P28: =IF(I28="FN",1,0) -> 0 | Q28: =IF(ISNUMBER(SEARCH("dual",LOWER(H28&" "&U28))),1,0) -> 0 | R28: ='03_Evaluacion_VR'!O9 -> Sí | S28: ='03_Evaluacion_VR'!R9 -> Sí | T28: ='03_Evaluacion_VR'!P9 -> Resultado_OB-001.png | U28: ='03_Evaluacion_VR'!S9 -> Resultado correcto: PowerShell legítimo no fue alertado. Control benigno para TEC-001.
A29: ='03_Evaluacion_VR'!A10 -> PR-009 | B29: ='03_Evaluacion_VR'!B10 -> OB-002 | C29: =IF(LEFT(B29,3)="TEC","TEC",IF(LEFT(B29,2)="OB","OB","")) -> OB | D29: =IF(C29="TEC",INDEX('01_Seleccion_Tecnicas'!$B:$B,MATCH(B29,'01_Seleccion_Tecnicas'!$A:$A,0)),INDEX('02_Operaciones_Benignas'!$B:$B,MATCH(B29,'02_Operaciones_Benignas'!$A:$A,0))) -> PowerShell con consulta de sistema | E29: =IF(C29="TEC",INDEX('01_Seleccion_Tecnicas'!$G:$G,MATCH(B29,'01_Seleccion_Tecnicas'!$A:$A,0)),INDEX('02_Operaciones_Benignas'!$B:$B,MATCH(B29,'02_Operaciones_Benignas'!$A:$A,0))) -> PowerShell con consulta de sistema | F29: ='03_Evaluacion_VR'!J10 -> No detectado | G29: ='03_Evaluacion_VR'!K10 -> Negativo | H29: ='03_Evaluacion_VR'!L10 -> verdadero negativo | I29: =IF(AND(G29="Positivo",F29="Detectado"),"VP",IF(AND(G29="Positivo",F29<>"Detectado"),"FN",IF(AND(G29="Negativo",F29="Detectado"),"FP",IF(AND(G29="Negativo",F29<>"Detectado"),"VN","NE")))) -> VN | J29: =IF(F29="Detectado",1,0) -> 0 | K29: =IF(G29="Positivo",1,0) -> 0 | L29: =IF(OR(I29="VP",I29="VN"),1,0) -> 1 | M29: =IF(I29="VP",1,0) -> 0 | N29: =IF(I29="VN",1,0) -> 1 | O29: =IF(I29="FP",1,0) -> 0 | P29: =IF(I29="FN",1,0) -> 0 | Q29: =IF(ISNUMBER(SEARCH("dual",LOWER(H29&" "&U29))),1,0) -> 0 | R29: ='03_Evaluacion_VR'!O10 -> Sí | S29: ='03_Evaluacion_VR'!R10 -> Sí | T29: ='03_Evaluacion_VR'!P10 -> Resultado_OB-002.png | U29: ='03_Evaluacion_VR'!S10 -> Resultado correcto: WMI/CIM administrativo no sensible no generó alerta de descubrimiento de software de seguridad.
A30: ='03_Evaluacion_VR'!A11 -> PR-010 | B30: ='03_Evaluacion_VR'!B11 -> OB-003 | C30: =IF(LEFT(B30,3)="TEC","TEC",IF(LEFT(B30,2)="OB","OB","")) -> OB | D30: =IF(C30="TEC",INDEX('01_Seleccion_Tecnicas'!$B:$B,MATCH(B30,'01_Seleccion_Tecnicas'!$A:$A,0)),INDEX('02_Operaciones_Benignas'!$B:$B,MATCH(B30,'02_Operaciones_Benignas'!$A:$A,0))) -> CMD benigno simple | E30: =IF(C30="TEC",INDEX('01_Seleccion_Tecnicas'!$G:$G,MATCH(B30,'01_Seleccion_Tecnicas'!$A:$A,0)),INDEX('02_Operaciones_Benignas'!$B:$B,MATCH(B30,'02_Operaciones_Benignas'!$A:$A,0))) -> CMD benigno simple | F30: ='03_Evaluacion_VR'!J11 -> No detectado | G30: ='03_Evaluacion_VR'!K11 -> Negativo | H30: ='03_Evaluacion_VR'!L11 -> verdadero negativo | I30: =IF(AND(G30="Positivo",F30="Detectado"),"VP",IF(AND(G30="Positivo",F30<>"Detectado"),"FN",IF(AND(G30="Negativo",F30="Detectado"),"FP",IF(AND(G30="Negativo",F30<>"Detectado"),"VN","NE")))) -> VN | J30: =IF(F30="Detectado",1,0) -> 0 | K30: =IF(G30="Positivo",1,0) -> 0 | L30: =IF(OR(I30="VP",I30="VN"),1,0) -> 1 | M30: =IF(I30="VP",1,0) -> 0 | N30: =IF(I30="VN",1,0) -> 1 | O30: =IF(I30="FP",1,0) -> 0 | P30: =IF(I30="FN",1,0) -> 0 | Q30: =IF(ISNUMBER(SEARCH("dual",LOWER(H30&" "&U30))),1,0) -> 0 | R30: ='03_Evaluacion_VR'!O11 -> Sí | S30: ='03_Evaluacion_VR'!R11 -> Sí | T30: ='03_Evaluacion_VR'!P11 -> Resultado_OB-003.png | U30: ='03_Evaluacion_VR'!S11 -> Resultado correcto: cmd.exe /c por sí solo no dispara la regla si no contiene marcadores de laboratorio.
A31: ='03_Evaluacion_VR'!A12 -> PR-011 | B31: ='03_Evaluacion_VR'!B12 -> OB-004 | C31: =IF(LEFT(B31,3)="TEC","TEC",IF(LEFT(B31,2)="OB","OB","")) -> OB | D31: =IF(C31="TEC",INDEX('01_Seleccion_Tecnicas'!$B:$B,MATCH(B31,'01_Seleccion_Tecnicas'!$A:$A,0)),INDEX('02_Operaciones_Benignas'!$B:$B,MATCH(B31,'02_Operaciones_Benignas'!$A:$A,0))) -> Consulta de directorio con CMD | E31: =IF(C31="TEC",INDEX('01_Seleccion_Tecnicas'!$G:$G,MATCH(B31,'01_Seleccion_Tecnicas'!$A:$A,0)),INDEX('02_Operaciones_Benignas'!$B:$B,MATCH(B31,'02_Operaciones_Benignas'!$A:$A,0))) -> Consulta de directorio con CMD | F31: ='03_Evaluacion_VR'!J12 -> No detectado | G31: ='03_Evaluacion_VR'!K12 -> Negativo | H31: ='03_Evaluacion_VR'!L12 -> verdadero negativo | I31: =IF(AND(G31="Positivo",F31="Detectado"),"VP",IF(AND(G31="Positivo",F31<>"Detectado"),"FN",IF(AND(G31="Negativo",F31="Detectado"),"FP",IF(AND(G31="Negativo",F31<>"Detectado"),"VN","NE")))) -> VN | J31: =IF(F31="Detectado",1,0) -> 0 | K31: =IF(G31="Positivo",1,0) -> 0 | L31: =IF(OR(I31="VP",I31="VN"),1,0) -> 1 | M31: =IF(I31="VP",1,0) -> 0 | N31: =IF(I31="VN",1,0) -> 1 | O31: =IF(I31="FP",1,0) -> 0 | P31: =IF(I31="FN",1,0) -> 0 | Q31: =IF(ISNUMBER(SEARCH("dual",LOWER(H31&" "&U31))),1,0) -> 0 | R31: ='03_Evaluacion_VR'!O12 -> Sí | S31: ='03_Evaluacion_VR'!R12 -> Sí | T31: ='03_Evaluacion_VR'!P12 -> Resultado_OB-004.png | U31: ='03_Evaluacion_VR'!S12 -> Resultado correcto: operación administrativa básica sin alerta.
A32: ='03_Evaluacion_VR'!A13 -> PR-012 | B32: ='03_Evaluacion_VR'!B13 -> OB-005 | C32: =IF(LEFT(B32,3)="TEC","TEC",IF(LEFT(B32,2)="OB","OB","")) -> OB | D32: =IF(C32="TEC",INDEX('01_Seleccion_Tecnicas'!$B:$B,MATCH(B32,'01_Seleccion_Tecnicas'!$A:$A,0)),INDEX('02_Operaciones_Benignas'!$B:$B,MATCH(B32,'02_Operaciones_Benignas'!$A:$A,0))) -> Consulta de tareas programadas | E32: =IF(C32="TEC",INDEX('01_Seleccion_Tecnicas'!$G:$G,MATCH(B32,'01_Seleccion_Tecnicas'!$A:$A,0)),INDEX('02_Operaciones_Benignas'!$B:$B,MATCH(B32,'02_Operaciones_Benignas'!$A:$A,0))) -> Consulta de tareas programadas | F32: ='03_Evaluacion_VR'!J13 -> No detectado | G32: ='03_Evaluacion_VR'!K13 -> Negativo | H32: ='03_Evaluacion_VR'!L13 -> verdadero negativo | I32: =IF(AND(G32="Positivo",F32="Detectado"),"VP",IF(AND(G32="Positivo",F32<>"Detectado"),"FN",IF(AND(G32="Negativo",F32="Detectado"),"FP",IF(AND(G32="Negativo",F32<>"Detectado"),"VN","NE")))) -> VN | J32: =IF(F32="Detectado",1,0) -> 0 | K32: =IF(G32="Positivo",1,0) -> 0 | L32: =IF(OR(I32="VP",I32="VN"),1,0) -> 1 | M32: =IF(I32="VP",1,0) -> 0 | N32: =IF(I32="VN",1,0) -> 1 | O32: =IF(I32="FP",1,0) -> 0 | P32: =IF(I32="FN",1,0) -> 0 | Q32: =IF(ISNUMBER(SEARCH("dual",LOWER(H32&" "&U32))),1,0) -> 0 | R32: ='03_Evaluacion_VR'!O13 -> Sí | S32: ='03_Evaluacion_VR'!R13 -> Sí | T32: ='03_Evaluacion_VR'!P13 -> Resultado_OB-005.png | U32: ='03_Evaluacion_VR'!S13 -> Resultado correcto: se diferencia consulta legítima de manipulación de tareas programadas.
... A42: ='03_Evaluacion_VR'!A23 -> PR-022 | B42: ='03_Evaluacion_VR'!B23 -> OB-015 | C42: =IF(LEFT(B42,3)="TEC","TEC",IF(LEFT(B42,2)="OB","OB","")) -> OB | D42: =IF(C42="TEC",INDEX('01_Seleccion_Tecnicas'!$B:$B,MATCH(B42,'01_Seleccion_Tecnicas'!$A:$A,0)),INDEX('02_Operaciones_Benignas'!$B:$B,MATCH(B42,'02_Operaciones_Benignas'!$A:$A,0))) -> Creación de archivo con extensión no .aes | E42: =IF(C42="TEC",INDEX('01_Seleccion_Tecnicas'!$G:$G,MATCH(B42,'01_Seleccion_Tecnicas'!$A:$A,0)),INDEX('02_Operaciones_Benignas'!$B:$B,MATCH(B42,'02_Operaciones_Benignas'!$A:$A,0))) -> Creación de archivo con extensión no .aes | F42: ='03_Evaluacion_VR'!J23 -> No detectado | G42: ='03_Evaluacion_VR'!K23 -> Negativo | H42: ='03_Evaluacion_VR'!L23 -> verdadero negativo | I42: =IF(AND(G42="Positivo",F42="Detectado"),"VP",IF(AND(G42="Positivo",F42<>"Detectado"),"FN",IF(AND(G42="Negativo",F42="Detectado"),"FP",IF(AND(G42="Negativo",F42<>"Detectado"),"VN","NE")))) -> VN | J42: =IF(F42="Detectado",1,0) -> 0 | K42: =IF(G42="Positivo",1,0) -> 0 | L42: =IF(OR(I42="VP",I42="VN"),1,0) -> 1 | M42: =IF(I42="VP",1,0) -> 0 | N42: =IF(I42="VN",1,0) -> 1 | O42: =IF(I42="FP",1,0) -> 0 | P42: =IF(I42="FN",1,0) -> 0 | Q42: =IF(ISNUMBER(SEARCH("dual",LOWER(H42&" "&U42))),1,0) -> 0 | R42: ='03_Evaluacion_VR'!O23 -> Sí | S42: ='03_Evaluacion_VR'!R23 -> Sí | T42: ='03_Evaluacion_VR'!P23 -> Resultado_OB-015.png | U42: ='03_Evaluacion_VR'!S23 -> Resultado correcto: la detección ransomware se mantiene centrada en .aes, rutas controladas y marcadores específicos.

Sheet 06_Graficos_técnicas
A1: Panel gráfico de resultados: detección, falsos positivos y cobertura MITRE
A3: GRÁFICAS
A37: Row Labels | B37: Cuenta de Clasificacion_Resultado
A38: verdadero negativo | B38: 14
A39: Clasificacion_Resultado | B39: 1
A40: Grand Total | B40: 15

Sheet 99_Leyenda
A1: 1. Significado de columnas
A2: ID_Tecnica_Interna | B2: Identificador interno único de cada técnica evaluada. Formato habitual: TEC-XXX
A3: Ground_Truth | B3: Resultado real esperado de la prueba. Indica si, en teoría, la técnica debía ser detectada o no.
A4: Clasificacion_Resultado | B4: Clasificación final del resultado comparando la detección observada con el resultado esperado. Valores típicos: VP, FN, FP, VN
A5: Impacto_Rendimiento | B5: Nivel cualitativo del impacto de la configuración o prueba sobre el sistema. Se basa en el efecto observado en métricas como CPU, RAM o I/O.
A8: 2. Prefijos
A9: TEC-XXX | B9: Identificador de técnica interna.
A10: BENCH-XXX | B10: Identificador de ejecución de benchmark o medición de rendimiento.
A11: VR-CONF-XXX | B11: Identificador de configuración de Velociraptor utilizada en la prueba.
A12: SNAP-XXX | B12: Identificador del snapshot o estado base de la máquina virtual.
A15: 3. Valores posibles
A16: Detectado | B16: La evidencia o comportamiento esperado fue identificado.
A17: No detectado | B17: No se observó la evidencia esperada.
A18: Parcial | B18: La técnica fue detectada solo de forma incompleta o ambigua.
A19: No evaluado | B19: La prueba no pudo completarse o no dispone de resultado válido.
A21: 4. Clasificación del resultado
A22: Verdadero positivo (VP) | B22: La técnica debía ser detectada y fue detectada.
A23: Falso negativo (FN) | B23: La técnica debía ser detectada y no fue detectada.
A24: Falso positivo (FP) | B24: La técnica no debía ser detectada, pero se marcó como detectada.
A25: Verdadero negativo (VN) | B25: La técnica no debía ser detectada y no fue detectada.
A28: 5. Impacto en rendimiento
A29: Nulo / no apreciable | B29: Sin impacto observable relevante.
A30: Bajo | B30: Impacto reducido, asumible en operación normal.
A31: Moderado | B31: Impacto visible, pero todavía aceptable.
A32: Alto | B32: Impacto relevante sobre el rendimiento del sistema.
A35: 6. ¿Cómo se calcula el impacto? | B35: El impacto se calcula comparando la condición MEDIDA de cada técnica frente a las tres mediciones BASE en el mismo entorno de laboratorio: misma VM, misma snapshot, misma configuración y Velociraptor activo. Se miden CPU, RAM, I/O lectura e I/O escritura.
A36: Fórmulas | B36: CPU_Delta_% = CPU_Medida_% - CPU_Base_% RAM_Delta_MB = RAM_Medida_MB - RAM_Base_MB IO_Read_Delta = IO_Read_Medida - IO_Read_Base IO_Write_Delta = IO_Write_Medida - IO_Write_Base
A37: Importante sobre RAM | B37: La RAM se mide con Memory\Available MBytes: RAM_Delta_MB < 0 → menos RAM disponible → más consumo real RAM_Delta_MB > 0 → más RAM disponible → menos consumo real
A38: Clasificación de Impacto_Rendimiento | B38: No evaluado → si falta CPU_Delta o RAM_Delta Bajo → si |CPU_Delta_%| < 5 y |RAM_Delta_MB| < 100 Medio → si |CPU_Delta_%| <= 15 y |RAM_Delta_MB| <= 300 Alto → en el resto de casos
A39: Nota | B39: La etiqueta Impacto_Rendimiento se clasifica con CPU y RAM I/O se calcula y se grafica, pero no entra en la etiqueta final
A42: 7. Siglas
A43: VR | B43: Velociraptor
A44: HIDS | B44: Host-based Intrusion Detection System
A45: MITRE ATT&CK | B45: marco de conocimiento de tácticas y técnicas de ataque
A46: IO | B46: entrada/salida (Input/Output)
A47: CPU | B47: unidad central de procesamiento
A48: RAM | B48: memoria de acceso aleatorio
A50: 6. Métricas resumen añadidas
A51: VP | B51: Verdadero positivo: técnica positiva detectada correctamente.
A52: VN | B52: Verdadero negativo: operación benigna no alertada.
...

Sheet 05_Datos_Graficos
A1: Datos auxiliares para gráficos - generados desde 04_Resumen
A3: Tipo | B3: Total | C3: Detectados | D3: Correctos | E3: VP | F3: VN | G3: FP | H3: FN
A4: TEC | B4: =COUNTIF('04_Resumen'!$C$21:$C$42,"TEC") -> 7 | C4: =SUMIFS('04_Resumen'!$J$21:$J$42,'04_Resumen'!$C$21:$C$42,"TEC") -> 7 | D4: =SUMIFS('04_Resumen'!$L$21:$L$42,'04_Resumen'!$C$21:$C$42,"TEC") -> 7 | E4: =SUMIFS('04_Resumen'!$M$21:$M$42,'04_Resumen'!$C$21:$C$42,"TEC") -> 7 | F4: =SUMIFS('04_Resumen'!$N$21:$N$42,'04_Resumen'!$C$21:$C$42,"TEC") -> 0 | G4: =SUMIFS('04_Resumen'!$O$21:$O$42,'04_Resumen'!$C$21:$C$42,"TEC") -> 0 | H4: =SUMIFS('04_Resumen'!$P$21:$P$42,'04_Resumen'!$C$21:$C$42,"TEC") -> 0
A5: OB | B5: =COUNTIF('04_Resumen'!$C$21:$C$42,"OB") -> 15 | C5: =SUMIFS('04_Resumen'!$J$21:$J$42,'04_Resumen'!$C$21:$C$42,"OB") -> 1 | D5: =SUMIFS('04_Resumen'!$L$21:$L$42,'04_Resumen'!$C$21:$C$42,"OB") -> 14 | E5: =SUMIFS('04_Resumen'!$M$21:$M$42,'04_Resumen'!$C$21:$C$42,"OB") -> 0 | F5: =SUMIFS('04_Resumen'!$N$21:$N$42,'04_Resumen'!$C$21:$C$42,"OB") -> 14 | G5: =SUMIFS('04_Resumen'!$O$21:$O$42,'04_Resumen'!$C$21:$C$42,"OB") -> 1 | H5: =SUMIFS('04_Resumen'!$P$21:$P$42,'04_Resumen'!$C$21:$C$42,"OB") -> 0
A8: Clase | B8: N | D8: Tasa | E8: Valor | G8: Táctica TEC | H8: N
A9: VP | B9: =SUM('04_Resumen'!$M$21:$M$42) -> 7 | D9: Detección TEC | E9: ='04_Resumen'!$B$11 -> 1 | G9: Execution | H9: =COUNTIF('04_Resumen'!$D$21:$D$27,"Execution") -> 3
A10: VN | B10: =SUM('04_Resumen'!$N$21:$N$42) -> 14 | D10: Falsos positivos OB | E10: ='04_Resumen'!$B$12 -> 0.066666667 | G10: Persistence | H10: =COUNTIF('04_Resumen'!$D$21:$D$27,"Persistence") -> 2
A11: FP | B11: =SUM('04_Resumen'!$O$21:$O$42) -> 1 | D11: Exactitud global | E11: ='04_Resumen'!$B$13 -> 0.95454545 | G11: Discovery | H11: =COUNTIF('04_Resumen'!$D$21:$D$27,"Discovery") -> 1
A12: FN | B12: =SUM('04_Resumen'!$P$21:$P$42) -> 0 | D12: Exactitud ajustada dual-use | E12: ='04_Resumen'!$B$15 -> 1 | G12: Impact | H12: =COUNTIF('04_Resumen'!$D$21:$D$27,"Impact") -> 1
A16: ID | B16: Tipo | C16: Detectado | D16: Correcto | E16: FP | F16: FN | G16: DualUse
A17: ='04_Resumen'!B21 -> TEC-001 | B17: ='04_Resumen'!C21 -> TEC | C17: ='04_Resumen'!J21 -> 1 | D17: ='04_Resumen'!L21 -> 1 | E17: ='04_Resumen'!O21 -> 0 | F17: ='04_Resumen'!P21 -> 0 | G17: ='04_Resumen'!Q21 -> 0
A18: ='04_Resumen'!B22 -> TEC-002 | B18: ='04_Resumen'!C22 -> TEC | C18: ='04_Resumen'!J22 -> 1 | D18: ='04_Resumen'!L22 -> 1 | E18: ='04_Resumen'!O22 -> 0 | F18: ='04_Resumen'!P22 -> 0 | G18: ='04_Resumen'!Q22 -> 0
A19: ='04_Resumen'!B23 -> TEC-003 | B19: ='04_Resumen'!C23 -> TEC | C19: ='04_Resumen'!J23 -> 1 | D19: ='04_Resumen'!L23 -> 1 | E19: ='04_Resumen'!O23 -> 0 | F19: ='04_Resumen'!P23 -> 0 | G19: ='04_Resumen'!Q23 -> 0
A20: ='04_Resumen'!B24 -> TEC-004 | B20: ='04_Resumen'!C24 -> TEC | C20: ='04_Resumen'!J24 -> 1 | D20: ='04_Resumen'!L24 -> 1 | E20: ='04_Resumen'!O24 -> 0 | F20: ='04_Resumen'!P24 -> 0 | G20: ='04_Resumen'!Q24 -> 0
A21: ='04_Resumen'!B25 -> TEC-005 | B21: ='04_Resumen'!C25 -> TEC | C21: ='04_Resumen'!J25 -> 1 | D21: ='04_Resumen'!L25 -> 1 | E21: ='04_Resumen'!O25 -> 0 | F21: ='04_Resumen'!P25 -> 0 | G21: ='04_Resumen'!Q25 -> 0
A22: ='04_Resumen'!B26 -> TEC-006 | B22: ='04_Resumen'!C26 -> TEC | C22: ='04_Resumen'!J26 -> 1 | D22: ='04_Resumen'!L26 -> 1 | E22: ='04_Resumen'!O26 -> 0 | F22: ='04_Resumen'!P26 -> 0 | G22: ='04_Resumen'!Q26 -> 0
A23: ='04_Resumen'!B27 -> TEC-007 | B23: ='04_Resumen'!C27 -> TEC | C23: ='04_Resumen'!J27 -> 1 | D23: ='04_Resumen'!L27 -> 1 | E23: ='04_Resumen'!O27 -> 0 | F23: ='04_Resumen'!P27 -> 0 | G23: ='04_Resumen'!Q27 -> 0
A24: ='04_Resumen'!B28 -> OB-001 | B24: ='04_Resumen'!C28 -> OB | C24: ='04_Resumen'!J28 -> 0 | D24: ='04_Resumen'!L28 -> 1 | E24: ='04_Resumen'!O28 -> 0 | F24: ='04_Resumen'!P28 -> 0 | G24: ='04_Resumen'!Q28 -> 0
A25: ='04_Resumen'!B29 -> OB-002 | B25: ='04_Resumen'!C29 -> OB | C25: ='04_Resumen'!J29 -> 0 | D25: ='04_Resumen'!L29 -> 1 | E25: ='04_Resumen'!O29 -> 0 | F25: ='04_Resumen'!P29 -> 0 | G25: ='04_Resumen'!Q29 -> 0
A26: ='04_Resumen'!B30 -> OB-003 | B26: ='04_Resumen'!C30 -> OB | C26: ='04_Resumen'!J30 -> 0 | D26: ='04_Resumen'!L30 -> 1 | E26: ='04_Resumen'!O30 -> 0 | F26: ='04_Resumen'!P30 -> 0 | G26: ='04_Resumen'!Q30 -> 0
A27: ='04_Resumen'!B31 -> OB-004 | B27: ='04_Resumen'!C31 -> OB | C27: ='04_Resumen'!J31 -> 0 | D27: ='04_Resumen'!L31 -> 1 | E27: ='04_Resumen'!O31 -> 0 | F27: ='04_Resumen'!P31 -> 0 | G27: ='04_Resumen'!Q31 -> 0
A28: ='04_Resumen'!B32 -> OB-005 | B28: ='04_Resumen'!C32 -> OB | C28: ='04_Resumen'!J32 -> 0 | D28: ='04_Resumen'!L32 -> 1 | E28: ='04_Resumen'!O32 -> 0 | F28: ='04_Resumen'!P32 -> 0 | G28: ='04_Resumen'!Q32 -> 0
... A38: ='04_Resumen'!B42 -> OB-015 | B38: ='04_Resumen'!C42 -> OB | C38: ='04_Resumen'!J42 -> 0 | D38: ='04_Resumen'!L42 -> 1 | E38: ='04_Resumen'!O42 -> 0 | F38: ='04_Resumen'!P42 -> 0 | G38: ='04_Resumen'!Q42 -> 0
