Workbook

Sheet 00_Instrucciones
A1: Tabla de control - Evaluación de artifacts públicos Velociraptor
A3: Objetivo | B3: Comprobar primero qué detectan los artifacts públicos antes de justificar artifacts personalizados P4-P1.
A4: Regla de uso | B4: No ejecutar todos a la vez. Seguir fases: F1 built-in básico → F2 Sigma/Hayabusa → F3 persistencia/triage → F4 opcional.
A5: Criterio Detecta = Sí | B5: El artifact genera un evento útil y atribuible a la técnica probada.
A6: Criterio Detecta = Parcial | B6: El artifact ve actividad base, pero no clasifica técnica, severidad o MITRE de forma suficiente.
A7: Criterio Detecta = No | B7: No genera evento útil pese a existir evidencia en el endpoint.
A8: Criterio Custom necesario = Sí | B8: La cobertura pública es insuficiente por falta de semántica MITRE, falso positivo, formato SOC, Discord o consumo.
A10: Orden práctico
A11: 1 | B11: Activar ProcessCreation, ServiceCreation y SysmonLogForward.
A12: 2 | B12: Ejecutar TEC-001 a TEC-009 una a una y rellenar la hoja 01_Control_Pruebas.
A13: 3 | B13: Ejecutar Windows.Hayabusa.Rules tras cada técnica.
A14: 4 | B14: Activar Windows.Hayabusa.Monitoring y repetir pruebas clave.
A15: 5 | B15: Usar persistence/triage solo después y como evidencia post-ejecución.
A16: 6 | B16: Con la hoja 04_Matriz_Resultados decidir qué gaps justifican artifacts custom.

Sheet 01_Seleccion_Tecnicas
A1: ID_Tecnica_Interna | B1: Táctica_MITRE | C1: ID_Táctica | D1: Técnica_MITRE | E1: ID_Técnica | F1: Subtécnica | G1: ID_Subtécnica | H1: Descripción | I1: Justificación_selección | J1: Observable_en_HOST | K1: Tipo_de_Evidencia_Host_Esperada | L1: Procedimiento_de_Prueba | M1: Criterio_de_Éxito | N1: Notas_Tecnicas | O1: Enlace_Referencia
A2: {="TEC-"&TEXT(ROW()-ROW(tblTecnicas[#Headers]),"000")} -> TEC-001 | B2: Execution | C2: TA0002 | D2: Command and Scripting Interpreter | E2: T1059 | F2: PowerShell | G2: T1059.001 | H2: Ejecución de comandos o scripts mediante PowerShell. | I2: Muy frecuente, muy visible en host y perfecta para una primera prueba. | J2: Sí | K2: Process Create | L2: Ejecutar powershell.exe con un script benigno local y parámetros visibles. | M2: Ver powershell.exe con Image, ParentImage y CommandLine coherentes. | N2: Empezar sin ofuscación; luego hacer una variante con argumentos más sospechosos. | O2: https://attack.mitre.org/techniques/T1059/001/
A3: {="TEC-"&TEXT(ROW()-ROW(tblTecnicas[#Headers]),"000")} -> TEC-002 | B3: Execution | C3: TA0002 | D3: Command and Scripting Interpreter | E3: T1059 | F3: Windows Command Shell | G3: T1059.003 | H3: Ejecución de comandos a través de cmd.exe. | I3: Muy simple de probar y muy trazable. | J3: Sí | K3: Process Create | L3: Lanzar cmd.exe con comandos benignos de prueba. | M3: Ver cmd.exe y su línea de comandos completa. | N3: Buena como baseline antes de PowerShell más complejo. | O3: https://attack.mitre.org/techniques/T1059/003
A4: {="TEC-"&TEXT(ROW()-ROW(tblTecnicas[#Headers]),"000")} -> TEC-003 | B4: Persistence | C4: TA0003 | D4: Scheduled Task/Job | E4: T1053 | F4: Scheduled Task | G4: T1053.005 | H4: Creación de una tarea programada para ejecutar un binario o script. | I4: Muy típica y fácil de reproducir de forma benigna. | J4: Sí | K4: Process Create | L4: Crear una tarea programada que ejecute una acción benigna y forzar su ejecución. | M4: Ver schtasks.exe y posteriormente el proceso lanzado por la tarea. | N4: Técnica multiuso; aquí la modelas como persistencia. | O4: https://attack.mitre.org/techniques/T1053/005
A5: {="TEC-"&TEXT(ROW()-ROW(tblTecnicas[#Headers]),"000")} -> TEC-004 | B5: Persistence | C5: TA0003 | D5: Boot or Logon Autostart Execution | E5: T1547 | F5: Registry Run Keys / Startup Folder - HKCU Run | G5: T1547.001 | H5: Persistencia mediante clave Run o carpeta de inicio. | I5: Clásica, muy justificable y con evidencia clara en registro. | J5: Sí | K5: Regisitry | L5: Crear una clave Run de prueba o usar Startup con un payload benigno. | M5: Ver evento de modificación de registro y, si aplica, la ejecución posterior al logon. | N5: Empezar por HKCU, no por HKLM. | O5: https://attack.mitre.org/techniques/T1547/001
A6: {="TEC-"&TEXT(ROW()-ROW(tblTecnicas[#Headers]),"000")} -> TEC-005 | B6: Execution | C6: TA0002 | D6: System Services | E6: T1569 | F6: Service Execution | G6: T1569.002 | H6: Ejecución de contenido a través de un servicio de Windows. | I6: Muy representativa y bastante simple. | J6: Sí | K6: Service | L6: Crear o modificar un servicio benigno y arrancarlo. | M6: Ver creación/modificación y arranque del servicio, además del proceso hijo. | N6: Mejor usar un servicio temporal de prueba y borrarlo al final. | O6: https://attack.mitre.org/techniques/T1569/002
A7: {="TEC-"&TEXT(ROW()-ROW(tblTecnicas[#Headers]),"000")} -> TEC-006 | B7: Discovery | C7: TA0007 | D7: Software Discovery | E7: T1518 | F7: Security Software Discovery | G7: T1518.001 | H7: Enumeración de software de seguridad o herramientas defensivas instaladas. | I7: Muy relevante antes de evasión y muy asumible en primeras pruebas. | J7: Sí | K7: Process Create | L7: Ejecutar una consulta benigna para listar AV, EDR o sensores instalados. | M7: Ver el proceso de consulta y su línea de comandos. | N7: Aquí solo discovery, sin desactivar nada. | O7: https://attack.mitre.org/techniques/T1518/001
A8: {="TEC-"&TEXT(ROW()-ROW(tblTecnicas[#Headers]),"000")} -> TEC-007 | B8: Impact | C8: TA0040 | D8: Data Encrypted for Impact | E8: T1486 | F8: N/A | G8: N/A | H8: Cifrado de ficheros para interrumpir la disponibilidad de la información. | I8: Técnica núcleo del foco ransomware del TFM. | J8: Sí | K8: Multiple | L8: Usar un simulador benigno que cifre o renombre solo archivos dummy en una carpeta de laboratorio. | M8: Ver el proceso lanzado y actividad anómala concentrada sobre la carpeta de prueba. | N8: Siempre con snapshot previo; nunca sobre datos reales. | O8: https://attack.mitre.org/techniques/T1486/
A9: TEC-008 | B9: Impact | C9: TA0040 | D9: Data Destruction | E9: T1485 | F9: N/A | G9: N/A | H9: Borrado controlado de ficheros para afectar a la disponibilidad e integridad de datos. | I9: Amplía el foco ransomware hacia sabotaje, técnica frecuente en escenarios insider. | J9: Sí | K9: Process Create; File Delete | L9: Ejecutar un script controlado que enumera y borra únicamente ficheros dummy dentro de C:\Users\Pruebas\dump. | M9: Ver powershell.exe ejecutando el script y eventos de borrado/ausencia final de los ficheros del directorio dump. | N9: Prueba limitada al directorio dump; no ejecutar sobre rutas reales ni de sistema. | O9: https://attack.mitre.org/techniques/T1485/
A10: TEC-009 | B10: Exfiltration | C10: TA0010 | D10: Automated Exfiltration / Exfiltration Over C2 Channel | E10: T1020 / T1041 | F10: N/A | G10: N/A | H10: Compresión y copia local de ficheros para simular exfiltración masiva sin salida real a Internet. | I10: Permite evaluar detección HIDS de preparación y staging de datos, sin usar infraestructura externa. | J10: Sí | K10: Process Create; File Create; Archive/ZIP | L10: Comprimir el contenido de C:\Users\Pruebas\dump en un ZIP y copiarlo a C:\Users\Pruebas\EXFIL como exfiltración simulada. | M10: Ver ejecución de powershell.exe, creación de ZIP y copia del archivo a la carpeta EXFIL. | N10: No usa SMTP, C2, nube ni credenciales reales; la exfiltración queda simulada a nivel host. | O10: https://attack.mitre.org/techniques/T1020/ ; https://attack.mitre.org/techniques/T1041/

Sheet 02_Operaciones_Benignas
A1: ID_Operación_Benigna | B1: Operación benigna | C1: Descripción | D1: Justificación_selección | E1: Observable_en_HOST | F1: Tipo_de_Evidencia_Host_Esperada | G1: Procedimiento_de_Prueba | H1: Criterio_de_Éxito | I1: Notas_Tecnicas | J1: Código_usado
A2: {="OB-"&TEXT(ROW()-ROW(tblTecnicas[#Headers]),"000")} -> OB-001 | B2: PowerShell administrativo básico | C2: Ejecución de PowerShell para consultar fecha y procesos, sin flags sospechosos ni marcadores TFM/TEC. | D2: Permite comprobar que el artifact no alerta por cualquier ejecución legítima de PowerShell. | E2: Sí: powershell.exe | F2: Sysmon Event ID 1 - ProcessCreation | G2: Ejecutar PowerShell con una consulta administrativa básica. | H2: La operación genera telemetría host, pero no alerta CU-TFM-001. | I2: Caso benigno de referencia para diferenciar uso administrativo de PowerShell frente a ejecución sospechosa con bypass, encodedcommand o marcadores de laboratorio. | J2: powershell.exe -Command "Get-Date; Get-Process | Select-Object -First 5"
A3: OB-002 | B3: PowerShell con consulta de sistema | C3: Consulta información básica del sistema operativo mediante Get-CimInstance. | D3: Permite validar que una consulta WMI/CIM genérica no se confunde con descubrimiento de software de seguridad. | E3: Sí: powershell.exe | F3: Sysmon Event ID 1 - ProcessCreation | G3: Ejecutar una consulta CIM sobre Win32_OperatingSystem. | H3: No debe generar alerta CU-TFM-006. | I3: Tras el ajuste, TEC-006 solo debe alertar si aparece SecurityCenter2 o AntivirusProduct. | J3: powershell.exe -Command "Get-CimInstance Win32_OperatingSystem | Select-Object Caption,Version"
A4: OB-003 | B4: CMD benigno simple | C4: Ejecución de cmd.exe /c para crear un fichero de texto sin marcadores TEC. | D4: Valida que no se alerta cualquier uso de cmd.exe. | E4: Sí: cmd.exe | F4: Sysmon Event ID 1 - ProcessCreation; posible Event ID 11 - FileCreate | G4: Crear un fichero benigno en C:\Users\Public. | H4: No debe generar alerta CU-TFM-002. | I4: No incluye TFM_CMD_TEST, TEC002_OK ni otros marcadores de laboratorio. | J4: cmd.exe /c echo prueba benigna > C:\Users\Public\benigno_cmd.txt
A5: OB-004 | B5: Consulta de directorio con CMD | C5: Listado de archivos mediante dir. | D5: Representa una operación normal de usuario o administración básica. | E5: Sí: cmd.exe | F5: Sysmon Event ID 1 - ProcessCreation | G5: Ejecutar un listado de directorio sobre C:\Users\Public. | H5: No debe generar alerta CU-TFM-002. | I5: Comprueba que el uso de cmd.exe /c por sí solo no dispara la regla. | J5: cmd.exe /c dir C:\Users\Public
A6: OB-005 | B6: Consulta de tareas programadas | C6: Enumeración de tareas existentes mediante schtasks /query. | D6: Distingue consulta legítima de creación o manipulación de tareas programadas. | E6: Sí: schtasks.exe | F6: Sysmon Event ID 1 - ProcessCreation | G6: Ejecutar una consulta de tareas programadas. | H6: No debe generar alerta CU-TFM-003. | I6: La consulta pasiva no representa ejecución ni persistencia. | J6: schtasks /query /fo LIST
A7: OB-006 | B7: Creación de tarea programada benigna | C7: Crea y elimina una tarea programada benigna sin marcadores TFM. | D7: Prueba actividad dual-use real: puede ser administración legítima o persistencia maliciosa. | E7: Sí: schtasks.exe | F7: Sysmon Event ID 1 - ProcessCreation | G7: Crear y eliminar una tarea programada benigna. | H7: Puede generar alerta CU-TFM-003; si alerta, se clasifica como falso positivo controlado o dual-use esperable. | I7: Se mantiene como detección amplia porque schtasks /create y /delete son relevantes en contexto SOC. | J7: schtasks /create /tn "Benign_Update_Check" /tr "cmd.exe /c echo benigno > C:\Users\Public\benign_task.txt" /sc once /st 23:59 && schtasks /delete /tn "Benign_Update_Check" /f
A8: OB-007 | B8: Consulta de Run Keys | C8: Consulta pasiva de claves Run del registro sin modificación. | D8: Diferencia enumeración legítima de persistencia mediante modificación de Run Keys. | E8: Sí: reg.exe | F8: Sysmon Event ID 1 - ProcessCreation | G8: Ejecutar reg query sobre HKCU\Software\Microsoft\Windows\CurrentVersion\Run. | H8: No debe generar alerta CU-TFM-004. | I8: Tras el ajuste, TEC-004 debe alertar solo ante add/delete, no ante query. | J8: reg query "HKCU\Software\Microsoft\Windows\CurrentVersion\Run"
A9: OB-008 | B9: Modificación benigna de clave no persistente | C9: Crea y elimina una clave de registro no relacionada con Run. | D9: Comprueba que la regla de persistencia no detecta cualquier modificación del registro. | E9: Sí: reg.exe | F9: Sysmon Event ID 1 - ProcessCreation | G9: Crear y eliminar una clave HKCU\Software\TFM_Benigno. | H9: No debe generar alerta CU-TFM-004. | I9: Aunque aparece TFM en la ruta, no afecta a CurrentVersion\Run, por lo que no debería mapear a T1547.001. | J9: reg add HKCU\Software\TFM_Benigno /v Test /t REG_SZ /d benigno /f && reg delete HKCU\Software\TFM_Benigno /f
A10: OB-009 | B10: Consulta de servicio Windows | C10: Consulta el estado de un servicio legítimo del sistema. | D10: Valida que no se detecta cualquier uso de sc.exe. | E10: Sí: sc.exe | F10: Sysmon Event ID 1 - ProcessCreation | G10: Ejecutar sc query sobre Spooler. | H10: No debe generar alerta CU-TFM-005. | I10: La consulta de servicio no implica creación ni ejecución de servicio. | J10: sc query Spooler
A11: OB-010 | B11: Consulta de servicio Windows Update | C11: Consulta el estado del servicio wuauserv sin modificarlo. | D11: Comprueba que operaciones administrativas pasivas sobre servicios no se clasifican como T1569.002. | E11: Sí: sc.exe | F11: Sysmon Event ID 1 - ProcessCreation | G11: Ejecutar sc query sobre wuauserv. | H11: No debe generar alerta CU-TFM-005. | I11: Se evita parar o arrancar servicios para no alterar el sistema. | J11: sc query wuauserv
A12: OB-011 | B12: Consulta WMI no sensible | C12: Consulta WMI genérica sobre el sistema operativo mediante wmic. | D12: Diferencia WMI administrativo de descubrimiento de antivirus o software de seguridad. | E12: Sí: wmic.exe | F12: Sysmon Event ID 1 - ProcessCreation | G12: Ejecutar wmic os get Caption,Version. | H12: No debe generar alerta CU-TFM-006. | I12: Tras el ajuste, TEC-006 debe requerir SecurityCenter2 o AntivirusProduct. | J12: wmic os get Caption,Version
A13: OB-012 | B13: Creación de archivos .txt | C13: Crea varios ficheros de texto no cifrados. | D13: Distingue actividad normal de escritura de archivos frente a creación de artefactos cifrados tipo ransomware. | E13: Sí: cmd.exe; creación de .txt | F13: Sysmon Event ID 1 - ProcessCreation; posible Event ID 11 - FileCreate | G13: Crear una carpeta y varios archivos .txt en C:\Users\Public. | H13: No debe generar alerta CU-TFM-007. | I13: No se usa extensión .aes ni rutas TEC-007_LAB/Ransomware. | J13: cmd.exe /c mkdir C:\Users\Public\benign_files & echo test > C:\Users\Public\benign_files\file1.txt & echo test > C:\Users\Public\benign_files\file2.txt
A14: OB-013 | B14: Copia de archivos | C14: Copia un fichero benigno a una carpeta de respaldo no asociada al laboratorio ransomware. | D14: Simula una operación normal de usuario o backup sin cifrado ni extensión sospechosa. | E14: Sí: cmd.exe; copy; creación en destino | F14: Sysmon Event ID 1 - ProcessCreation; posible Event ID 11 - FileCreate | G14: Copiar file1.txt a una carpeta benign_backup. | H14: No debe generar alerta CU-TFM-007. | I14: Evita rutas Ransomware, TEC-007_LAB y extensión .aes para medir falsos positivos. | J14: cmd.exe /c mkdir C:\Users\Public\benign_backup & copy C:\Users\Public\benign_files\file1.txt C:\Users\Public\benign_backup\file1_copy.txt
... A16: OB-015 | B16: Creación de archivo con extensión no .aes | C16: Crea un archivo .bak benigno. | D16: Verifica que la detección no alerta por cualquier extensión distinta a .txt. | E16: Sí: cmd.exe; creación de .bak | F16: Sysmon Event ID 1 - ProcessCreation; posible Event ID 11 - FileCreate | G16: Crear un archivo file1.bak en carpeta benigna. | H16: No debe generar alerta CU-TFM-007. | I16: Valida que la regla ransomware se centra en .aes y marcadores/rutas controladas. | J16: cmd.exe /c echo backup > C:\Users\Public\benign_files\file1.bak

Sheet 03_Evaluacion_VR
A1: ID_Prueba | B1: ID_Interna | C1: Evidencia_Host_Observada | D1: Escenario_Prueba | E1: VM_Snapshot_ID | F1: Version_Velociraptor | G1: Artefacto_VR_Usado | H1: Tipo_Artefacto | I1: Modo_Ejecución | J1: Resultado_Detección | K1: Ground_Truth | L1: Clasificacion_Resultado | M1: Resumen_Evidencia | N1: Tiempo_Hasta_Evidencia | O1: Replicable | P1: Ref_Captura_Log_Anexo | Q1: Fuente_Telemetria_Host | R1: Deteccion_VR_OK | S1: Comentario
A2: ="PR-"&TEXT(ROW()-1,"000") -> PR-001 | B2: TEC-001 | C2: EventID 1 (Process Create) con Image = powershell.exe, CommandLine = powershell.exe -NoProfile -ExecutionPolicy Bypass -File prueba_ps.ps1 y ParentImage = cmd.exe | D2: Ejecución controlada de script benigno local mediante PowerShell | E2: 02_VR_Con_Artifacts_Funcionando | F2: 0.75.6 | G2: Custom.TFM.Alert.Process/Sysmon_Process_File_UseCases | H2: Event artifact | I2: Client Event | J2: Detectado | K2: Positivo | L2: verdadero positivo | M2: Velociraptor mostró un evento Sysmon del canal Microsoft-Windows-Sysmon/Operational con EventID = 1, donde se observó la ejecución de powershell.exe, su línea de comandos y el proceso padre cmd.exe | N2: <5 min | O2: Sí | P2: Resultado_TEC-001.png | Q2: Windows.EventLogs.Evtx | R2: Sí | S2: La detección es válida, pero en este artifact la información útil aparece embebida en Message, no en columnas separadas
A3: ="PR-"&TEXT(ROW()-1,"000") -> PR-002 | B3: TEC-002 | C3: Proceso cmd.exe con CommandLine conteniendo el marcador TEC002_OK; ParentCommandLine asociado a C:\Windows\Explorer.EXE; aparición coherente de procesos hijo como conhost.exe y timeout.exe. | D3: Ejecución benigna controlada de cmd.exe para crear un fichero temporal mediante echo, incluyendo una variante con timeout para mejorar la observabilidad. | E3: 02_VR_Con_Artifacts_Funcionando | F3: 0.75.6 | G3: Custom.TFM.Alert.Process/Sysmon_Process_File_UseCases | H3: Event artifact | I3: Client Event | J3: Detectado | K3: Positivo | L3: verdadero positivo | M3: Velociraptor registró cmd.exe con la línea de comandos de la prueba y el marcador TEC002_OK, con relación padre-hijo coherente respecto a explorer.exe. | N3: <5 min | O3: Sí | P3: Resultado_TEC-002.png | Q3: Sysmon Event ID 1 — Process Create | R3: Sí | S3: La variante con timeout fue más robusta que la ejecución demasiado corta. Resultado válido como prueba base de ejecución vía shell.
A4: ="PR-"&TEXT(ROW()-1,"000") -> PR-003 | B4: TEC-003 | C4: Creación de tarea programada TFM-TEC-003, ejecución de schtasks.exe, ejecución de cmd.exe y creación de C:\Users\Public\tec003_ok.txt | D4: Creación manual de tarea programada benigna y ejecución forzada con schtasks /run | E4: 03_TFM_Montado_Configurado | F4: 0.75.6 | G4: Custom.TFM.Alert.Process/Sysmon_Process_File_UseCases | H4: Event artifact | I4: Client Event | J4: Detectado | K4: Positivo | L4: verdadero positivo | M4: Se creó la tarea TFM-TEC-003, se ejecutó manualmente y se generó correctamente el fichero de evidencia | N4: <5 min | O4: Sí | P4: Resultado_TEC-003.png | Q4: Sysmon Event ID 1 — Process Create | R4: Sí | S4: Técnica validada correctamente; la ejecución final funcionó al usar comando directo en la tarea programada
A5: ="PR-"&TEXT(ROW()-1,"000") -> PR-004 | B5: TEC-004 | C5: Clave HKCU\Software\Microsoft\Windows\CurrentVersion\Run con valor TFM_T1547_001_test → C:\Windows\System32\calc.exe; procesos reg.exe (add/delete) y ejecución de calc.exe tras logon. | D5: VM Windows 10 aislada; usuario estándar seguridad; script batch TFM_T1547_001.bat que crea y elimina persistencia T1547.001 apuntando a calc.exe. | E5: 04_Antes_de_persistencia | F5: 0.75.6 | G5: Custom.TFM.Alert.Process/Sysmon_Process_File_UseCases | H5: Event artifact | I5: Client Event | J5: Detectado | K5: Positivo | L5: verdadero positivo | M5: Eventos de reg.exe con reg add/delete HKCU\...\Run TFM_T1547_001_test invocados desde cmd.exe (parent Explorer.EXE); presencia temporal del valor Run en StartupItems. | N5: <5 min | O5: Sí | P5: Resultado_TEC-004.png | Q5: Lectura del registro de usuario (HKCU Run). | R5: Sí | S5: Caso de bajo riesgo usando binario legítimo (calc.exe) como payload benigno; escenario ideal para ilustrar T1547.001 con alta trazabilidad y limpieza sencilla en entorno académico.
A6: ="PR-"&TEXT(ROW()-1,"000") -> PR-005 | B6: TEC-005 | C6: Creacion de servicio temporal TFM_TEC005_20260406_151223 con binPath C:\Windows\System32\cmd.exe /c echo ServicioEjecutado_20260406_151223 > "C:\Users\seguridad\Desktop\TFM\Pruebas\TEC005\TFM_TEC005_20260406_151223.txt"; generacion correcta del fichero de evidencia y posterior borrado del servicio. | D6: VM Windows 10 aislada; usuario seguridad; PowerShell como administrador; script sc.ps1 que crea, arranca, verifica y elimina un servicio temporal benigno para T1569.002. | E6: 04_Antes_de_persistencia | F6: 0.75.6 | G6: Custom.TFM.Alert.Process/Sysmon_Process_File_UseCases | H6: Event artifact | I6: Client Event | J6: Detectado | K6: Positivo | L6: verdadero positivo | M6: Evento 7045 capturado en Velociraptor con nombre de servicio TFM_TEC005_20260406_151223, DisplayName TFM TEC005 Test Service e ImagePath apuntando a cmd.exe /c echo ServicioEjecutado_20260406_151223 > "...TFM_TEC005_20260406_151223.txt"; evidencia host generada correctamente y limpieza final del servicio completada. | N6: <5 min | O6: Sí | P6: Resultado_TEC-005.png & Resultado_TEC-005.2.png | Q6: Log System / Service Control Manager (7045) y evidencia host en fichero de salida. | R6: Sí | S6: Caso benigno, trazable y de bajo riesgo para ilustrar T1569.002 mediante creacion y ejecucion de un servicio temporal; alta claridad forense y limpieza sencilla para entorno academico.
A7: ="PR-"&TEXT(ROW()-1,"000") -> PR-006 | B7: TEC-006 | C7: Ejecución de powershell.exe con -File TEC006.ps1, powershell.exe con Get-CimInstance -Namespace 'root/SecurityCenter2' -ClassName 'AntivirusProduct', cmd.exe y WMIC.exe con consulta wmic /namespace:\\root\SecurityCenter2 path AntivirusProduct get displayName,productState | D7: VM Windows 10 aislada; usuario seguridad; PowerShell como administrador; script sc.ps1 que crea, arranca, verifica y elimina un servicio temporal benigno para T1569.002. | E7: 05_Despues_de_ransom | F7: 0.75.6 | G7: Custom.TFM.Alert.Process/Sysmon_Process_File_UseCases | H7: Event artifact | I7: Client Event | J7: Detectado | K7: Positivo | L7: verdadero positivo | M7: Sysmon Event ID 1 con CommandLine completa de TEC006.ps1, Get-CimInstance y WMIC sobre SecurityCenter2/AntivirusProduct; cadena powershell → cmd → WMIC | N7: <5 min | O7: Sí | P7: Resultado_TEC-006.png & Resultado_TEC-006.2.png | Q7: Sysmon Operational / Event ID 1 | R7: Sí | S7: Se descarta Windows.Events.ProcessCreation como evidencia principal por menor claridad; SysmonLogForward ofrece trazabilidad más sólida
A8: ="PR-"&TEXT(ROW()-1,"000") -> PR-007 | B8: TEC-007 | C8: Ejecución de powershell.exe con Scriptransom.ps1 (Sysmon ID 1), creación/escritura de artefactos asociados al ataque (Sysmon ID 11), presencia final de archivos .aes en TEC-007_LAB, presencia de copias en backups y ausencia final de temp_*.aes. No se observaron eventos ID 23/26 de borrado. | D8: Simulación controlada de cifrado AES sobre ficheros dummy, con copia previa a backups, borrado del original y movimiento interno del temporal cifrado a .aes final. | E8: 05_Despues_de_ransom | F8: 0.75.6 | G8: Custom.TFM.Alert.Process/Sysmon_Process_File_UseCases | H8: Event artifact | I8: Client Event | J8: Detectado | K8: Positivo | L8: verdadero positivo | M8: Velociraptor detectó la ejecución del script mediante Sysmon ID 1 y mostró eventos ID 11 coherentes con creación/escritura de artefactos del ataque. El estado final del host confirmó la presencia de .aes en la carpeta atacada y de backups del original. | N8: <5 min | O8: Sí | P8: Resultado_TEC-007.png & Resultado_TEC-007.2.png & Resultado_TEC-007.3.png & Resultado_TEC-007.4.png & Resultado_TEC-007.5.png & Resultado_TEC-007.6.png & Resultado_TEC-007.7.png | Q8: Sysmon (Microsoft-Windows-Sysmon/Operational) + estado del sistema de ficheros mediante glob() | R8: Sí | S8: Detección parcial-fuerte. Se demuestra ejecución e impacto final compatibles con T1486, pero no se observaron eventos FileDelete (ID 23/26) en la configuración activa de Sysmon. El paso temp_*.aes -> *.aes final se interpreta como move/rename interno inferido, no como evento explícito.
A9: ="PR-"&TEXT(ROW()-1,"000") -> PR-008 | B9: TEC-008 | C9: Ejecución de powershell.exe con TEC-008_sabotaje_controlado.ps1; enumeración recursiva de C:\Users\Pruebas\dump; borrado masivo de ficheros dummy mediante Remove-Item; eventos de proceso y eliminación de ficheros sobre TargetFilename dentro de dump. | D9: Simulación controlada de sabotaje mediante borrado masivo de archivos dummy dentro de C:\Users\Pruebas\dump, sin afectar a otras rutas del sistema y sin persistencia, evasión ni propagación. | E9: 07_Sabotaje_Exfiltracion_Dummy | F9: 0.75.6 | G9: Custom.TFM.Alert.Process/Sysmon_Process_File_UseCases | H9: Event artifact | I9: Client Event | J9: Detectado | K9: Positivo | L9: verdadero positivo | M9: Velociraptor registró la ejecución de PowerShell y evidencias coherentes de destrucción controlada sobre el directorio dump; la actividad quedó acotada a archivos dummy del laboratorio. | N9: <5 min | O9: Sí | P9: Resultado_TEC-008.png | Q9: Sysmon Event ID 1 — Process Create; Sysmon Event ID 23/26 — File Delete si están habilitados; TargetFilename en C:\Users\Pruebas\dump | R9: Sí | S9: La técnica permite evaluar la capacidad de Velociraptor para observar comportamientos de sabotaje host-based mediante eliminación masiva de archivos en un directorio controlado.
A10: ="PR-"&TEXT(ROW()-1,"000") -> PR-009 | B10: TEC-009 | C10: Ejecución de powershell.exe con TEC-009_exfiltracion_simulada.ps1; enumeración de C:\Users\Pruebas\dump; compresión mediante Compress-Archive; creación de archivo ZIP y copia local a C:\Users\Pruebas\EXFIL. | D10: Simulación controlada de exfiltración host-based mediante compresión y copia local de información dummy a una carpeta EXFIL, sin envío real a Internet ni uso de C2, SMTP, nube o credenciales reales. | E10: 07_Sabotaje_Exfiltracion_Dummy | F10: 0.75.6 | G10: Custom.TFM.Alert.Process/Sysmon_Process_File_UseCases | H10: Event artifact | I10: Client Event | J10: Detectado | K10: Positivo | L10: verdadero positivo | M10: Velociraptor registró la ejecución de PowerShell, la creación del archivo ZIP y la copia local del paquete hacia EXFIL, simulando staging/exfiltración sin transmisión externa. | N10: <5 min | O10: Sí | P10: Resultado_TEC-009.png | Q10: Sysmon Event ID 1 — Process Create; Sysmon Event ID 11 — File Create; eventos de creación/modificación de ZIP y copia en C:\Users\Pruebas\EXFIL | R10: Sí | S10: La técnica permite evaluar la capacidad de Velociraptor para detectar patrones de exfiltración host-based, especialmente compresión, empaquetado y copia de información desde una ubicación sensible simulada.
A11: ="PR-"&TEXT(ROW()-1,"000") -> PR-010 | B11: OB-001 | C11: Sysmon Event ID 1 asociado a powershell.exe con CommandLine = powershell.exe -Command "Get-Date; Get-Process | Select-Object -First 5" y ParentImage = cmd.exe. | D11: Validación de operaciones benignas para evaluación de falsos positivos del artifact | E11: 06_Validacion_FP_Artifact_Ajustado | F11: 0.75.6 | G11: Custom.TFM.Alert.Process/Sysmon_Process_File_UseCases | H11: Event artifact | I11: Client Event | J11: No detectado | K11: Negativo | L11: verdadero negativo | M11: La operación generó telemetría host normal de creación de proceso, pero el artifact no la clasificó como TEC-001 al no existir flags sospechosos ni marcadores TFM/TEC. | N11: No aplica | O11: Sí | P11: Resultado_OB-001.png | Q11: Sysmon Operational / Event ID 1 | R11: Sí | S11: Resultado correcto: PowerShell legítimo no fue alertado. Control benigno para TEC-001.
A12: ="PR-"&TEXT(ROW()-1,"000") -> PR-011 | B12: OB-002 | C12: Sysmon Event ID 1 asociado a powershell.exe con CommandLine = powershell.exe -Command "Get-CimInstance Win32_OperatingSystem | Select-Object Caption,Version". | D12: Validación de operaciones benignas para evaluación de falsos positivos del artifact | E12: 06_Validacion_FP_Artifact_Ajustado | F12: 0.75.6 | G12: Custom.TFM.Alert.Process/Sysmon_Process_File_UseCases | H12: Event artifact | I12: Client Event | J12: No detectado | K12: Negativo | L12: verdadero negativo | M12: La consulta CIM/WMI genérica del sistema operativo generó telemetría host, pero no fue clasificada como TEC-006 tras restringir la regla a SecurityCenter2/AntivirusProduct. | N12: No aplica | O12: Sí | P12: Resultado_OB-002.png | Q12: Sysmon Operational / Event ID 1 | R12: Sí | S12: Resultado correcto: WMI/CIM administrativo no sensible no generó alerta de descubrimiento de software de seguridad.
A13: ="PR-"&TEXT(ROW()-1,"000") -> PR-012 | B13: OB-003 | C13: Sysmon Event ID 1 asociado a cmd.exe con CommandLine = cmd.exe /c echo prueba benigna > C:\Users\Public\benigno_cmd.txt. | D13: Validación de operaciones benignas para evaluación de falsos positivos del artifact | E13: 06_Validacion_FP_Artifact_Ajustado | F13: 0.75.6 | G13: Custom.TFM.Alert.Process/Sysmon_Process_File_UseCases | H13: Event artifact | I13: Client Event | J13: No detectado | K13: Negativo | L13: verdadero negativo | M13: La ejecución de cmd.exe creó un fichero de texto benigno sin marcadores TEC002_OK ni TFM_CMD_TEST, por lo que no se generó alerta TEC-002. | N13: No aplica | O13: Sí | P13: Resultado_OB-003.png | Q13: Sysmon Operational / Event ID 1; posible Event ID 11 | R13: Sí | S13: Resultado correcto: cmd.exe /c por sí solo no dispara la regla si no contiene marcadores de laboratorio.
... A25: ="PR-"&TEXT(ROW()-1,"000") -> PR-024 | B25: OB-015 | C25: Sysmon Event ID 1 asociado a cmd.exe y posible Event ID 11 por creación de file1.bak en C:\Users\Public\benign_files. | D25: Validación de operaciones benignas para evaluación de falsos positivos del artifact | E25: 06_Validacion_FP_Artifact_Ajustado | F25: 0.75.6 | G25: Custom.TFM.Alert.Process/Sysmon_Process_File_UseCases | H25: Event artifact | I25: Client Event | J25: No detectado | K25: Negativo | L25: verdadero negativo | M25: La creación de un archivo .bak no activó TEC-007, confirmando que la regla no alerta por cualquier extensión no común. | N25: No aplica | O25: Sí | P25: Resultado_OB-015.png | Q25: Sysmon Operational / Event ID 1; posible Event ID 11 | R25: Sí | S25: Resultado correcto: la detección ransomware se mantiene centrada en .aes, rutas controladas y marcadores específicos.
A26: ="PR-"&TEXT(ROW()-1,"000") -> PR-025
A27: ="PR-"&TEXT(ROW()-1,"000") -> PR-026
A28: ="PR-"&TEXT(ROW()-1,"000") -> PR-027
A29: ="PR-"&TEXT(ROW()-1,"000") -> PR-028
A30: ="PR-"&TEXT(ROW()-1,"000") -> PR-029
A31: ="PR-"&TEXT(ROW()-1,"000") -> PR-030
A32: ="PR-"&TEXT(ROW()-1,"000") -> PR-031
A33: ="PR-"&TEXT(ROW()-1,"000") -> PR-032
A34: ="PR-"&TEXT(ROW()-1,"000") -> PR-033
A35: ="PR-"&TEXT(ROW()-1,"000") -> PR-034
A36: ="PR-"&TEXT(ROW()-1,"000") -> PR-035
A37: ="PR-"&TEXT(ROW()-1,"000") -> PR-036
... A100: ="PR-"&TEXT(ROW()-1,"000") -> PR-099

Sheet 04_Resumen
A1: Resumen final de evaluación: técnicas MITRE + operaciones benignas
A3: Indicador | B3: Valor | C3: Interpretación | E3: Lectura técnica para la memoria
A4: Total de pruebas | B4: =COUNTA($A$21:$A$44) -> 24 | C4: TEC + OB evaluadas | E4: 1 | F4: La cobertura de detección sobre las siete técnicas TEC fue completa: VP = 7 y FN = 0.
A5: Técnicas TEC evaluadas | B5: =COUNTIF($C$21:$C$44,"TEC") -> 9 | C5: Pruebas positivas esperadas | E5: 2 | F5: Las operaciones benignas validan discriminación: 14/15 fueron verdaderos negativos.
A6: Operaciones benignas OB | B6: =COUNTIF($C$21:$C$44,"OB") -> 15 | C6: Pruebas negativas esperadas | E6: 3 | F6: El único falso positivo corresponde a OB-006, una creación/eliminación de tarea programada; se clasifica como dual-use controlado.
A7: Verdaderos positivos (VP) | B7: =SUM($M$21:$M$44) -> 9 | C7: Técnicas detectadas correctamente | E7: 4 | F7: La tasa de FP por operación benigna queda acotada y es coherente con un artifact SOC-style orientado a superficie de exposición.
A8: Verdaderos negativos (VN) | B8: =SUM($N$21:$N$44) -> 14 | C8: Operaciones benignas no alertadas
A9: Falsos positivos (FP) | B9: =SUM($O$21:$O$44) -> 1 | C9: OB que generaron alerta | E9: Reglas de clasificación usadas en la hoja
A10: Falsos negativos (FN) | B10: =SUM($P$21:$P$44) -> 0 | C10: TEC no detectadas | E10: VP | F10: Ground_Truth = Positivo y Resultado_Detección = Detectado.
A11: Tasa detección TEC | B11: =IF(B5=0,0,B7/B5) -> 1 | C11: VP / TEC | E11: FN | F11: Ground_Truth = Positivo y Resultado_Detección distinto de Detectado.
A12: Tasa FP OB | B12: =IF(B6=0,0,B9/B6) -> 0.066666667 | C12: FP / OB | E12: VN | F12: Ground_Truth = Negativo y Resultado_Detección distinto de Detectado.
A13: Exactitud global | B13: =IF(B4=0,0,(B7+B8)/B4) -> 0.95833333 | C13: (VP + VN) / Total | E13: FP | F13: Ground_Truth = Negativo y Resultado_Detección = Detectado.
A14: Alertas dual-use controladas | B14: =SUM($Q$21:$Q$44) -> 1 | C14: FP esperable por comportamiento dual-use | E14: Dual-use | F14: Clasificación o comentario contiene dual-use/controlado; se conserva como FP, pero se interpreta con contexto SOC.
A15: Exactitud operativa ajustada | B15: =IF(B4=0,0,(B7+B8+B14)/B4) -> 1 | C15: (VP + VN + dual-use) / Total
A20: ID_Prueba | B20: ID_Interna | C20: Tipo | D20: Grupo/Operación | E20: MITRE/Técnica | F20: Resultado_Detección | G20: Ground_Truth | H20: Clasificacion_Resultado | I20: Clase_Normalizada | J20: Detectado_Bin | K20: GroundTruth_Bin | L20: Correcto_Bin | M20: VP_Bin | N20: VN_Bin | O20: FP_Bin | P20: FN_Bin | Q20: DualUse_Bin | R20: Replicable | S20: Deteccion_VR_OK | T20: Ref_Captura | U20: Comentario_TFM
A21: PR-001 | B21: TEC-001 | C21: =IF(LEFT(B21,3)="TEC","TEC",IF(LEFT(B21,2)="OB","OB","")) -> TEC | D21: Execution | E21: T1059.001 | F21: Detectado | G21: Positivo | H21: verdadero positivo | I21: =IF(AND(G21="Positivo",F21="Detectado"),"VP",IF(AND(G21="Positivo",F21<>"Detectado"),"FN",IF(AND(G21="Negativo",F21="Detectado"),"FP",IF(AND(G21="Negativo",F21<>"Detectado"),"VN","NE")))) -> VP | J21: =IF(F21="Detectado",1,0) -> 1 | K21: =IF(G21="Positivo",1,0) -> 1 | L21: =IF(OR(I21="VP",I21="VN"),1,0) -> 1 | M21: =IF(I21="VP",1,0) -> 1 | N21: =IF(I21="VN",1,0) -> 0 | O21: =IF(I21="FP",1,0) -> 0 | P21: =IF(I21="FN",1,0) -> 0 | Q21: =IF(ISNUMBER(SEARCH("dual",LOWER(H21&" "&U21))),1,0) -> 0 | R21: Sí | S21: Sí | T21: Resultado_TEC-001.png | U21: La detección es válida, pero en este artifact la información útil aparece embebida en Message, no en columnas separadas
A22: PR-002 | B22: TEC-002 | C22: =IF(LEFT(B22,3)="TEC","TEC",IF(LEFT(B22,2)="OB","OB","")) -> TEC | D22: Execution | E22: T1059.003 | F22: Detectado | G22: Positivo | H22: verdadero positivo | I22: =IF(AND(G22="Positivo",F22="Detectado"),"VP",IF(AND(G22="Positivo",F22<>"Detectado"),"FN",IF(AND(G22="Negativo",F22="Detectado"),"FP",IF(AND(G22="Negativo",F22<>"Detectado"),"VN","NE")))) -> VP | J22: =IF(F22="Detectado",1,0) -> 1 | K22: =IF(G22="Positivo",1,0) -> 1 | L22: =IF(OR(I22="VP",I22="VN"),1,0) -> 1 | M22: =IF(I22="VP",1,0) -> 1 | N22: =IF(I22="VN",1,0) -> 0 | O22: =IF(I22="FP",1,0) -> 0 | P22: =IF(I22="FN",1,0) -> 0 | Q22: =IF(ISNUMBER(SEARCH("dual",LOWER(H22&" "&U22))),1,0) -> 0 | R22: Sí | S22: Sí | T22: Resultado_TEC-002.png | U22: La variante con timeout fue más robusta que la ejecución demasiado corta. Resultado válido como prueba base de ejecución vía shell.
A23: PR-003 | B23: TEC-003 | C23: =IF(LEFT(B23,3)="TEC","TEC",IF(LEFT(B23,2)="OB","OB","")) -> TEC | D23: Persistence | E23: T1053.005 | F23: Detectado | G23: Positivo | H23: verdadero positivo | I23: =IF(AND(G23="Positivo",F23="Detectado"),"VP",IF(AND(G23="Positivo",F23<>"Detectado"),"FN",IF(AND(G23="Negativo",F23="Detectado"),"FP",IF(AND(G23="Negativo",F23<>"Detectado"),"VN","NE")))) -> VP | J23: =IF(F23="Detectado",1,0) -> 1 | K23: =IF(G23="Positivo",1,0) -> 1 | L23: =IF(OR(I23="VP",I23="VN"),1,0) -> 1 | M23: =IF(I23="VP",1,0) -> 1 | N23: =IF(I23="VN",1,0) -> 0 | O23: =IF(I23="FP",1,0) -> 0 | P23: =IF(I23="FN",1,0) -> 0 | Q23: =IF(ISNUMBER(SEARCH("dual",LOWER(H23&" "&U23))),1,0) -> 0 | R23: Sí | S23: Sí | T23: Resultado_TEC-003.png | U23: Técnica validada correctamente; la ejecución final funcionó al usar comando directo en la tarea programada
A24: PR-004 | B24: TEC-004 | C24: =IF(LEFT(B24,3)="TEC","TEC",IF(LEFT(B24,2)="OB","OB","")) -> TEC | D24: Persistence | E24: T1547.001 | F24: Detectado | G24: Positivo | H24: verdadero positivo | I24: =IF(AND(G24="Positivo",F24="Detectado"),"VP",IF(AND(G24="Positivo",F24<>"Detectado"),"FN",IF(AND(G24="Negativo",F24="Detectado"),"FP",IF(AND(G24="Negativo",F24<>"Detectado"),"VN","NE")))) -> VP | J24: =IF(F24="Detectado",1,0) -> 1 | K24: =IF(G24="Positivo",1,0) -> 1 | L24: =IF(OR(I24="VP",I24="VN"),1,0) -> 1 | M24: =IF(I24="VP",1,0) -> 1 | N24: =IF(I24="VN",1,0) -> 0 | O24: =IF(I24="FP",1,0) -> 0 | P24: =IF(I24="FN",1,0) -> 0 | Q24: =IF(ISNUMBER(SEARCH("dual",LOWER(H24&" "&U24))),1,0) -> 0 | R24: Sí | S24: Sí | T24: Resultado_TEC-004.png | U24: Caso de bajo riesgo usando binario legítimo (calc.exe) como payload benigno; escenario ideal para ilustrar T1547.001 con alta trazabilidad y limpieza sencilla en entorno académico.
A25: PR-005 | B25: TEC-005 | C25: =IF(LEFT(B25,3)="TEC","TEC",IF(LEFT(B25,2)="OB","OB","")) -> TEC | D25: Execution | E25: T1569.002 | F25: Detectado | G25: Positivo | H25: verdadero positivo | I25: =IF(AND(G25="Positivo",F25="Detectado"),"VP",IF(AND(G25="Positivo",F25<>"Detectado"),"FN",IF(AND(G25="Negativo",F25="Detectado"),"FP",IF(AND(G25="Negativo",F25<>"Detectado"),"VN","NE")))) -> VP | J25: =IF(F25="Detectado",1,0) -> 1 | K25: =IF(G25="Positivo",1,0) -> 1 | L25: =IF(OR(I25="VP",I25="VN"),1,0) -> 1 | M25: =IF(I25="VP",1,0) -> 1 | N25: =IF(I25="VN",1,0) -> 0 | O25: =IF(I25="FP",1,0) -> 0 | P25: =IF(I25="FN",1,0) -> 0 | Q25: =IF(ISNUMBER(SEARCH("dual",LOWER(H25&" "&U25))),1,0) -> 0 | R25: Sí | S25: Sí | T25: Resultado_TEC-005.png & Resultado_TEC-005.2.png | U25: Caso benigno, trazable y de bajo riesgo para ilustrar T1569.002 mediante creacion y ejecucion de un servicio temporal; alta claridad forense y limpieza sencilla para entorno academico.
A26: PR-006 | B26: TEC-006 | C26: =IF(LEFT(B26,3)="TEC","TEC",IF(LEFT(B26,2)="OB","OB","")) -> TEC | D26: Discovery | E26: T1518.001 | F26: Detectado | G26: Positivo | H26: verdadero positivo | I26: =IF(AND(G26="Positivo",F26="Detectado"),"VP",IF(AND(G26="Positivo",F26<>"Detectado"),"FN",IF(AND(G26="Negativo",F26="Detectado"),"FP",IF(AND(G26="Negativo",F26<>"Detectado"),"VN","NE")))) -> VP | J26: =IF(F26="Detectado",1,0) -> 1 | K26: =IF(G26="Positivo",1,0) -> 1 | L26: =IF(OR(I26="VP",I26="VN"),1,0) -> 1 | M26: =IF(I26="VP",1,0) -> 1 | N26: =IF(I26="VN",1,0) -> 0 | O26: =IF(I26="FP",1,0) -> 0 | P26: =IF(I26="FN",1,0) -> 0 | Q26: =IF(ISNUMBER(SEARCH("dual",LOWER(H26&" "&U26))),1,0) -> 0 | R26: Sí | S26: Sí | T26: Resultado_TEC-006.png & Resultado_TEC-006.2.png | U26: Se descarta Windows.Events.ProcessCreation como evidencia principal por menor claridad; SysmonLogForward ofrece trazabilidad más sólida
A27: PR-007 | B27: TEC-007 | C27: =IF(LEFT(B27,3)="TEC","TEC",IF(LEFT(B27,2)="OB","OB","")) -> TEC | D27: Impact | E27: T1486 | F27: Detectado | G27: Positivo | H27: verdadero positivo | I27: =IF(AND(G27="Positivo",F27="Detectado"),"VP",IF(AND(G27="Positivo",F27<>"Detectado"),"FN",IF(AND(G27="Negativo",F27="Detectado"),"FP",IF(AND(G27="Negativo",F27<>"Detectado"),"VN","NE")))) -> VP | J27: =IF(F27="Detectado",1,0) -> 1 | K27: =IF(G27="Positivo",1,0) -> 1 | L27: =IF(OR(I27="VP",I27="VN"),1,0) -> 1 | M27: =IF(I27="VP",1,0) -> 1 | N27: =IF(I27="VN",1,0) -> 0 | O27: =IF(I27="FP",1,0) -> 0 | P27: =IF(I27="FN",1,0) -> 0 | Q27: =IF(ISNUMBER(SEARCH("dual",LOWER(H27&" "&U27))),1,0) -> 0 | R27: Sí | S27: Sí | T27: Resultado_TEC-007.png & Resultado_TEC-007.2.png & Resultado_TEC-007.3.png & Resultado_TEC-007.4.png & Resultado_TEC-007.5.png & Resultado_TEC-007.6.png & Resultado_TEC-007.7.png | U27: Detección parcial-fuerte. Se demuestra ejecución e impacto final compatibles con T1486, pero no se observaron eventos FileDelete (ID 23/26) en la configuración activa de Sysmon. El paso temp_*.aes -> *.aes final se interpreta como move/rename interno inferido, no como evento explícito.
A28: PR-008 | B28: TEC-008 | C28: =IF(LEFT(B28,3)="TEC","TEC",IF(LEFT(B28,2)="OB","OB","")) -> TEC | D28: Impact | E28: T1485 | F28: Detectado | G28: Positivo | H28: verdadero positivo | I28: =IF(AND(G28="Positivo",F28="Detectado"),"VP",IF(AND(G28="Positivo",F28<>"Detectado"),"FN",IF(AND(G28="Negativo",F28="Detectado"),"FP",IF(AND(G28="Negativo",F28<>"Detectado"),"VN","NE")))) -> VP | J28: =IF(F28="Detectado",1,0) -> 1 | K28: =IF(G28="Positivo",1,0) -> 1 | L28: =IF(OR(I28="VP",I28="VN"),1,0) -> 1 | M28: =IF(I28="VP",1,0) -> 1 | N28: =IF(I28="VN",1,0) -> 0 | O28: =IF(I28="FP",1,0) -> 0 | P28: =IF(I28="FN",1,0) -> 0 | Q28: =IF(ISNUMBER(SEARCH("dual",LOWER(H28&" "&U28))),1,0) -> 0 | R28: Sí | S28: Sí | T28: Resultado_TEC-008.png | U28: La técnica permite evaluar la capacidad de Velociraptor para observar comportamientos de sabotaje host-based mediante eliminación masiva de archivos en un directorio controlado.
A29: PR-009 | B29: TEC-009 | C29: =IF(LEFT(B29,3)="TEC","TEC",IF(LEFT(B29,2)="OB","OB","")) -> TEC | D29: Exfiltration | E29: T1020 / T1041 | F29: Detectado | G29: Positivo | H29: verdadero positivo | I29: =IF(AND(G29="Positivo",F29="Detectado"),"VP",IF(AND(G29="Positivo",F29<>"Detectado"),"FN",IF(AND(G29="Negativo",F29="Detectado"),"FP",IF(AND(G29="Negativo",F29<>"Detectado"),"VN","NE")))) -> VP | J29: =IF(F29="Detectado",1,0) -> 1 | K29: =IF(G29="Positivo",1,0) -> 1 | L29: =IF(OR(I29="VP",I29="VN"),1,0) -> 1 | M29: =IF(I29="VP",1,0) -> 1 | N29: =IF(I29="VN",1,0) -> 0 | O29: =IF(I29="FP",1,0) -> 0 | P29: =IF(I29="FN",1,0) -> 0 | Q29: =IF(ISNUMBER(SEARCH("dual",LOWER(H29&" "&U29))),1,0) -> 0 | R29: Sí | S29: Sí | T29: Resultado_TEC-009.png | U29: La técnica permite evaluar la capacidad de Velociraptor para detectar patrones de exfiltración host-based, especialmente compresión, empaquetado y copia de información desde una ubicación sensible simulada.
A30: PR-010 | B30: OB-001 | C30: =IF(LEFT(B30,3)="TEC","TEC",IF(LEFT(B30,2)="OB","OB","")) -> OB | D30: PowerShell administrativo básico | E30: PowerShell administrativo básico | F30: No detectado | G30: Negativo | H30: verdadero negativo | I30: =IF(AND(G30="Positivo",F30="Detectado"),"VP",IF(AND(G30="Positivo",F30<>"Detectado"),"FN",IF(AND(G30="Negativo",F30="Detectado"),"FP",IF(AND(G30="Negativo",F30<>"Detectado"),"VN","NE")))) -> VN | J30: =IF(F30="Detectado",1,0) -> 0 | K30: =IF(G30="Positivo",1,0) -> 0 | L30: =IF(OR(I30="VP",I30="VN"),1,0) -> 1 | M30: =IF(I30="VP",1,0) -> 0 | N30: =IF(I30="VN",1,0) -> 1 | O30: =IF(I30="FP",1,0) -> 0 | P30: =IF(I30="FN",1,0) -> 0 | Q30: =IF(ISNUMBER(SEARCH("dual",LOWER(H30&" "&U30))),1,0) -> 0 | R30: Sí | S30: Sí | T30: Resultado_OB-001.png | U30: Resultado correcto: PowerShell legítimo no fue alertado. Control benigno para TEC-001.
A31: PR-011 | B31: OB-002 | C31: =IF(LEFT(B31,3)="TEC","TEC",IF(LEFT(B31,2)="OB","OB","")) -> OB | D31: PowerShell con consulta de sistema | E31: PowerShell con consulta de sistema | F31: No detectado | G31: Negativo | H31: verdadero negativo | I31: =IF(AND(G31="Positivo",F31="Detectado"),"VP",IF(AND(G31="Positivo",F31<>"Detectado"),"FN",IF(AND(G31="Negativo",F31="Detectado"),"FP",IF(AND(G31="Negativo",F31<>"Detectado"),"VN","NE")))) -> VN | J31: =IF(F31="Detectado",1,0) -> 0 | K31: =IF(G31="Positivo",1,0) -> 0 | L31: =IF(OR(I31="VP",I31="VN"),1,0) -> 1 | M31: =IF(I31="VP",1,0) -> 0 | N31: =IF(I31="VN",1,0) -> 1 | O31: =IF(I31="FP",1,0) -> 0 | P31: =IF(I31="FN",1,0) -> 0 | Q31: =IF(ISNUMBER(SEARCH("dual",LOWER(H31&" "&U31))),1,0) -> 0 | R31: Sí | S31: Sí | T31: Resultado_OB-002.png | U31: Resultado correcto: WMI/CIM administrativo no sensible no generó alerta de descubrimiento de software de seguridad.
A32: PR-012 | B32: OB-003 | C32: =IF(LEFT(B32,3)="TEC","TEC",IF(LEFT(B32,2)="OB","OB","")) -> OB | D32: CMD benigno simple | E32: CMD benigno simple | F32: No detectado | G32: Negativo | H32: verdadero negativo | I32: =IF(AND(G32="Positivo",F32="Detectado"),"VP",IF(AND(G32="Positivo",F32<>"Detectado"),"FN",IF(AND(G32="Negativo",F32="Detectado"),"FP",IF(AND(G32="Negativo",F32<>"Detectado"),"VN","NE")))) -> VN | J32: =IF(F32="Detectado",1,0) -> 0 | K32: =IF(G32="Positivo",1,0) -> 0 | L32: =IF(OR(I32="VP",I32="VN"),1,0) -> 1 | M32: =IF(I32="VP",1,0) -> 0 | N32: =IF(I32="VN",1,0) -> 1 | O32: =IF(I32="FP",1,0) -> 0 | P32: =IF(I32="FN",1,0) -> 0 | Q32: =IF(ISNUMBER(SEARCH("dual",LOWER(H32&" "&U32))),1,0) -> 0 | R32: Sí | S32: Sí | T32: Resultado_OB-003.png | U32: Resultado correcto: cmd.exe /c por sí solo no dispara la regla si no contiene marcadores de laboratorio.
... A44: PR-024 | B44: OB-015 | C44: =IF(LEFT(B44,3)="TEC","TEC",IF(LEFT(B44,2)="OB","OB","")) -> OB | D44: Creación de archivo con extensión no .aes | E44: Creación de archivo con extensión no .aes | F44: No detectado | G44: Negativo | H44: verdadero negativo | I44: =IF(AND(G44="Positivo",F44="Detectado"),"VP",IF(AND(G44="Positivo",F44<>"Detectado"),"FN",IF(AND(G44="Negativo",F44="Detectado"),"FP",IF(AND(G44="Negativo",F44<>"Detectado"),"VN","NE")))) -> VN | J44: =IF(F44="Detectado",1,0) -> 0 | K44: =IF(G44="Positivo",1,0) -> 0 | L44: =IF(OR(I44="VP",I44="VN"),1,0) -> 1 | M44: =IF(I44="VP",1,0) -> 0 | N44: =IF(I44="VN",1,0) -> 1 | O44: =IF(I44="FP",1,0) -> 0 | P44: =IF(I44="FN",1,0) -> 0 | Q44: =IF(ISNUMBER(SEARCH("dual",LOWER(H44&" "&U44))),1,0) -> 0 | R44: Sí | S44: Sí | T44: Resultado_OB-015.png | U44: Resultado correcto: la detección ransomware se mantiene centrada en .aes, rutas controladas y marcadores específicos.

Sheet 05_Datos_Graficos
A1: Datos auxiliares para gráficos - generados desde 04_Resumen
A3: Tipo | B3: Total | C3: Detectados | D3: Correctos | E3: VP | F3: VN | G3: FP | H3: FN
A4: TEC | B4: 9 | C4: 9 | D4: 9 | E4: 9 | F4: 0 | G4: 0 | H4: 0
A5: OB | B5: 15 | C5: 1 | D5: 14 | E5: 0 | F5: 14 | G5: 1 | H5: 0
A8: Clase | B8: N | D8: Tasa | E8: Valor | G8: Táctica TEC | H8: N
A9: VP | B9: 9 | D9: Detección TEC | E9: 1 | G9: Execution | H9: 3
A10: VN | B10: 14 | D10: Falsos positivos OB | E10: 0.066666667 | G10: Persistence | H10: 2
A11: FP | B11: 1 | D11: Exactitud global | E11: 0.95833333 | G11: Discovery | H11: 1
A12: FN | B12: 0 | D12: Exactitud ajustada dual-use | E12: 1 | G12: Impact | H12: 2
G13: Exfiltration | H13: 1
A16: ID | B16: Tipo | C16: Detectado | D16: Correcto | E16: FP | F16: FN | G16: DualUse
A17: TEC-001 | B17: TEC | C17: 1 | D17: 1 | E17: 0 | F17: 0 | G17: 0
A18: TEC-002 | B18: TEC | C18: 1 | D18: 1 | E18: 0 | F18: 0 | G18: 0
A19: TEC-003 | B19: TEC | C19: 1 | D19: 1 | E19: 0 | F19: 0 | G19: 0
A20: TEC-004 | B20: TEC | C20: 1 | D20: 1 | E20: 0 | F20: 0 | G20: 0
A21: TEC-005 | B21: TEC | C21: 1 | D21: 1 | E21: 0 | F21: 0 | G21: 0
A22: TEC-006 | B22: TEC | C22: 1 | D22: 1 | E22: 0 | F22: 0 | G22: 0
A23: TEC-007 | B23: TEC | C23: 1 | D23: 1 | E23: 0 | F23: 0 | G23: 0
A24: TEC-008 | B24: TEC | C24: 1 | D24: 1 | E24: 0 | F24: 0 | G24: 0
A25: TEC-009 | B25: TEC | C25: 1 | D25: 1 | E25: 0 | F25: 0 | G25: 0
A26: OB-001 | B26: OB | C26: 0 | D26: 1 | E26: 0 | F26: 0 | G26: 0
A27: OB-002 | B27: OB | C27: 0 | D27: 1 | E27: 0 | F27: 0 | G27: 0
A28: OB-003 | B28: OB | C28: 0 | D28: 1 | E28: 0 | F28: 0 | G28: 0
... A40: OB-015 | B40: OB | C40: 0 | D40: 1 | E40: 0 | F40: 0 | G40: 0

Sheet 06_Control_Pruebas
A1: ID_Prueba | B1: Fase | C1: Perfil | D1: Artifact_Publico | E1: Modo | F1: Fuente | G1: TEC | H1: MITRE | I1: Táctica | J1: Objetivo_Prueba | K1: Configuración | L1: Evidencia_Esperada | M1: Importado/Disponible | N1: Activado/Ejecutado | O1: Técnica_Ejecutada | P1: Evento_Base_Visto | Q1: Detección | R1: Calidad_Detección | S1: Severity/Level | T1: Regla/Title | U1: EventID/Channel | V1: Evidencia_Guardada | W1: Necesita_Custom | X1: Comentario
A2: PUB-001 | B2: F1 Built-in básico | C2: P4 Low | D2: Windows.Events.ProcessCreation | E2: CLIENT_EVENT | F2: Process creation | G2: TEC-001 | H2: T1059.001 | I2: Execution | J2: Comprobar visibilidad de PowerShell sospechoso | K2: Client Monitoring activo | L2: powershell.exe con -NoProfile / -ExecutionPolicy Bypass | M2: Pendiente | N2: Pendiente | O2: Pendiente | P2: Pendiente | Q2: Pendiente | R2: Pendiente | V2: Pendiente | W2: Pendiente
A3: PUB-002 | B3: F1 Built-in básico | C3: P4 Low | D3: Windows.Events.ProcessCreation | E3: CLIENT_EVENT | F3: Process creation | G3: TEC-002 | H3: T1059.003 | I3: Execution | J3: Comprobar visibilidad de cmd.exe y encadenamiento | K3: Client Monitoring activo | L3: cmd.exe /c, whoami, reg, net o llamada desde PowerShell | M3: Pendiente | N3: Pendiente | O3: Pendiente | P3: Pendiente | Q3: Pendiente | R3: Pendiente | V3: Pendiente | W3: Pendiente
A4: PUB-003 | B4: F1 Built-in básico | C4: P4 Low | D4: Windows.Events.ProcessCreation | E4: CLIENT_EVENT | F4: Process creation | G4: TEC-003 | H4: T1053.005 | I4: Execution / Persistence | J4: Comprobar visibilidad de schtasks.exe | K4: Client Monitoring activo | L4: schtasks /create /run /delete | M4: Pendiente | N4: Pendiente | O4: Pendiente | P4: Pendiente | Q4: Pendiente | R4: Pendiente | V4: Pendiente | W4: Pendiente
A5: PUB-004 | B5: F1 Built-in básico | C5: P4 Low | D5: Windows.Events.ProcessCreation | E5: CLIENT_EVENT | F5: Process creation | G5: TEC-004 | H5: T1547.001 | I5: Persistence | J5: Comprobar visibilidad de reg.exe sobre Run/RunOnce | K5: Client Monitoring activo | L5: reg add/delete HKCU\...\Run | M5: Pendiente | N5: Pendiente | O5: Pendiente | P5: Pendiente | Q5: Pendiente | R5: Pendiente | V5: Pendiente | W5: Pendiente
A6: PUB-005 | B6: F1 Built-in básico | C6: P4 Low | D6: Windows.Events.ProcessCreation | E6: CLIENT_EVENT | F6: Process creation | G6: TEC-005 | H6: T1569.002 | I6: Execution | J6: Comprobar visibilidad de sc.exe | K6: Client Monitoring activo | L6: sc create/start/delete | M6: Pendiente | N6: Pendiente | O6: Pendiente | P6: Pendiente | Q6: Pendiente | R6: Pendiente | V6: Pendiente | W6: Pendiente
A7: PUB-006 | B7: F1 Built-in básico | C7: P4 Low | D7: Windows.Events.ProcessCreation | E7: CLIENT_EVENT | F7: Process creation | G7: TEC-006 | H7: T1518.001 | I7: Discovery | J7: Comprobar visibilidad de discovery de AV/EDR | K7: Client Monitoring activo | L7: PowerShell/WMI/WMIC consultando root\SecurityCenter2 o AntivirusProduct | M7: Pendiente | N7: Pendiente | O7: Pendiente | P7: Pendiente | Q7: Pendiente | R7: Pendiente | V7: Pendiente | W7: Pendiente
A8: PUB-007 | B8: F1 Built-in básico | C8: P4 Low | D8: Windows.Events.ProcessCreation | E8: CLIENT_EVENT | F8: Process creation | G8: TEC-007 | H8: T1486 | I8: Impact | J8: Comprobar visibilidad mínima de ejecución del script de cifrado | K8: Client Monitoring activo | L8: powershell.exe ejecutando lógica de cifrado controlado | M8: Pendiente | N8: Pendiente | O8: Pendiente | P8: Pendiente | Q8: Pendiente | R8: Pendiente | V8: Pendiente | W8: Sí | X8: Esperable detección solo parcial: ve proceso, no lógica crypto
A9: PUB-008 | B9: F1 Built-in básico | C9: P4 Low | D9: Windows.Events.ProcessCreation | E9: CLIENT_EVENT | F9: Process creation | G9: TEC-008 | H9: T1485 | I9: Impact | J9: Comprobar visibilidad mínima de borrado destructivo | K9: Client Monitoring activo | L9: powershell.exe con Remove-Item / borrado masivo | M9: Pendiente | N9: Pendiente | O9: Pendiente | P9: Pendiente | Q9: Pendiente | R9: Pendiente | V9: Pendiente | W9: Sí | X9: Esperable detección parcial: ve proceso, no intención destructiva
A10: PUB-009 | B10: F1 Built-in básico | C10: P4 Low | D10: Windows.Events.ProcessCreation | E10: CLIENT_EVENT | F10: Process creation | G10: TEC-009 | H10: T1074.001 / T1560.001 | I10: Collection | J10: Comprobar visibilidad mínima de staging/archivo | K10: Client Monitoring activo | L10: powershell.exe con Compress-Archive / Copy-Item | M10: Pendiente | N10: Pendiente | O10: Pendiente | P10: Pendiente | Q10: Pendiente | R10: Pendiente | V10: Pendiente | W10: Sí | X10: Si no hay red externa, clasificar como Collection/staging
A11: PUB-010 | B11: F1 Built-in básico | C11: P4 Low | D11: Windows.Events.ServiceCreation | E11: CLIENT_EVENT | F11: System 7045 | G11: TEC-005 | H11: T1569.002 | I11: Execution | J11: Comprobar creación de servicio mediante Event ID 7045 | K11: Client Monitoring activo | L11: EventID 7045 con ServiceName e ImagePath | M11: Pendiente | N11: Pendiente | O11: Pendiente | P11: Pendiente | Q11: Pendiente | R11: Pendiente | V11: Pendiente | W11: Parcial | X11: Muy útil para servicio, pero no cubre resto de técnicas
A12: PUB-011 | B12: F1 Built-in básico | C12: P4 Low | D12: Windows.Sysinternals.SysmonLogForward | E12: CLIENT_EVENT | F12: Sysmon Operational | G12: TEC-001/002/003/005/006 | H12: Varios | I12: Execution / Discovery | J12: Comprobar reenvío de eventos Sysmon ID 1 | K12: Sysmon activo + artifact activo | L12: Sysmon ID 1 con Image, CommandLine y ParentImage | M12: Pendiente | N12: Pendiente | O12: Pendiente | P12: Pendiente | Q12: Pendiente | R12: Pendiente | V12: Pendiente | W12: Parcial | X12: Base de evidencia, no alerta semántica
A13: PUB-012 | B13: F1 Built-in básico | C13: P4 Low | D13: Windows.Sysinternals.SysmonLogForward | E13: CLIENT_EVENT | F13: Sysmon Operational | G13: TEC-004 | H13: T1547.001 | I13: Persistence | J13: Comprobar reenvío de Sysmon 12/13/14 para Run Keys | K13: Sysmon Registry events activos | L13: EventID 12/13/14 sobre Run/RunOnce | M13: Pendiente | N13: Pendiente | O13: Pendiente | P13: Pendiente | Q13: Pendiente | R13: Pendiente | V13: Pendiente | W13: Parcial | X13: Útil como evidencia de registro
A14: PUB-013 | B14: F1 Built-in básico | C14: P4 Low/P2 High | D14: Windows.Sysinternals.SysmonLogForward | E14: CLIENT_EVENT | F14: Sysmon Operational | G14: TEC-008 | H14: T1485 | I14: Impact | J14: Comprobar evidencia de borrado real con Sysmon ID 26 | K14: Sysmon ID 26 activo | L14: FileDeleteDetected / TargetFilename | M14: Pendiente | N14: Pendiente | O14: Pendiente | P14: Pendiente | Q14: Pendiente | R14: Pendiente | V14: Pendiente | W14: Sí | X14: No usar como Discord por fichero; evidencia forense
A15: PUB-014 | B15: F1 Built-in básico | C15: P4 Low/P2 High | D15: Windows.Sysinternals.SysmonLogForward | E15: CLIENT_EVENT | F15: Sysmon Operational | G15: TEC-009 | H15: T1074.001 / T1560.001 / T1041 contextual | I15: Collection / Exfiltration contextual | J15: Comprobar Sysmon ID 11/3/22 para ZIP y posible salida externa | K15: Sysmon FileCreate/Network/DNS activos | L15: FileCreate .zip y, si procede, NetworkConnect externo | M15: Pendiente | N15: Pendiente | O15: Pendiente | P15: Pendiente | Q15: Pendiente | R15: Pendiente | V15: Pendiente | W15: Sí | X15: T1041 solo si hay conexión externa real
A16: PUB-015 | B16: F2 Sigma/Hayabusa histórico | C16: P3 Medium | D16: Windows.Hayabusa.Rules | E16: CLIENT / Hunt | F16: EVTX + Sigma/Hayabusa | G16: TEC-001 | H16: T1059.001 | I16: Execution | J16: Evaluar detección Sigma histórica de PowerShell | K16: RuleLevel Critical/High; luego Medium si no detecta | L16: RuleTitle, Level, EventID, ATT&CK tags | M16: Pendiente | N16: Pendiente | O16: Pendiente | P16: Pendiente | Q16: Pendiente | R16: Pendiente | V16: Pendiente | W16: Pendiente
A17: PUB-016 | B17: F2 Sigma/Hayabusa histórico | C17: P3 Medium | D17: Windows.Hayabusa.Rules | E17: CLIENT / Hunt | F17: EVTX + Sigma/Hayabusa | G17: TEC-002 | H17: T1059.003 | I17: Execution | J17: Evaluar detección Sigma histórica de CMD | K17: Critical/High; luego Medium | L17: Regla Sigma/Hayabusa asociada a cmd o LOLBins | M17: Pendiente | N17: Pendiente | O17: Pendiente | P17: Pendiente | Q17: Pendiente | R17: Pendiente | V17: Pendiente | W17: Pendiente
A18: PUB-017 | B18: F2 Sigma/Hayabusa histórico | C18: P3 Medium | D18: Windows.Hayabusa.Rules | E18: CLIENT / Hunt | F18: EVTX + Sigma/Hayabusa | G18: TEC-003 | H18: T1053.005 | I18: Execution / Persistence | J18: Evaluar detección histórica de Scheduled Task | K18: Critical/High; luego Medium | L18: Regla sobre schtasks / Task Scheduler | M18: Pendiente | N18: Pendiente | O18: Pendiente | P18: Pendiente | Q18: Pendiente | R18: Pendiente | V18: Pendiente | W18: Pendiente
A19: PUB-018 | B19: F2 Sigma/Hayabusa histórico | C19: P3 Medium | D19: Windows.Hayabusa.Rules | E19: CLIENT / Hunt | F19: EVTX + Sigma/Hayabusa | G19: TEC-004 | H19: T1547.001 | I19: Persistence | J19: Evaluar detección histórica de Run Keys | K19: Critical/High; luego Medium | L19: Regla sobre Registry Run Key / Startup | M19: Pendiente | N19: Pendiente | O19: Pendiente | P19: Pendiente | Q19: Pendiente | R19: Pendiente | V19: Pendiente | W19: Pendiente
A20: PUB-019 | B20: F2 Sigma/Hayabusa histórico | C20: P3 Medium | D20: Windows.Hayabusa.Rules | E20: CLIENT / Hunt | F20: EVTX + Sigma/Hayabusa | G20: TEC-005 | H20: T1569.002 | I20: Execution | J20: Evaluar detección histórica de servicio | K20: Critical/High; luego Medium | L20: Regla sobre Service Creation / EventID 7045 | M20: Pendiente | N20: Pendiente | O20: Pendiente | P20: Pendiente | Q20: Pendiente | R20: Pendiente | V20: Pendiente | W20: Pendiente
A21: PUB-020 | B21: F2 Sigma/Hayabusa histórico | C21: P3 Medium | D21: Windows.Hayabusa.Rules | E21: CLIENT / Hunt | F21: EVTX + Sigma/Hayabusa | G21: TEC-006 | H21: T1518.001 | I21: Discovery | J21: Evaluar detección histórica de Security Software Discovery | K21: Critical/High; luego Medium | L21: Regla sobre SecurityCenter2 / AntivirusProduct / Defender | M21: Pendiente | N21: Pendiente | O21: Pendiente | P21: Pendiente | Q21: Pendiente | R21: Pendiente | V21: Pendiente | W21: Pendiente
A22: PUB-021 | B22: F2 Sigma/Hayabusa histórico | C22: P3 Medium | D22: Windows.Hayabusa.Rules | E22: CLIENT / Hunt | F22: EVTX + Sigma/Hayabusa | G22: TEC-007 | H22: T1486 | I22: Impact | J22: Evaluar detección histórica de comportamiento ransomware | K22: Critical/High; luego Medium | L22: Regla sobre crypto/ransomware/extensiones/ciphering si existe | M22: Pendiente | N22: Pendiente | O22: Pendiente | P22: Pendiente | Q22: Pendiente | R22: Pendiente | V22: Pendiente | W22: Sí | X22: Probable cobertura parcial si el script es controlado y benigno
A23: PUB-022 | B23: F2 Sigma/Hayabusa histórico | C23: P3 Medium | D23: Windows.Hayabusa.Rules | E23: CLIENT / Hunt | F23: EVTX + Sigma/Hayabusa | G23: TEC-008 | H23: T1485 | I23: Impact | J23: Evaluar detección histórica de data destruction | K23: Critical/High; luego Medium | L23: Regla sobre Remove-Item / delete / destruction si existe | M23: Pendiente | N23: Pendiente | O23: Pendiente | P23: Pendiente | Q23: Pendiente | R23: Pendiente | V23: Pendiente | W23: Sí | X23: Puede no detectar si no coincide con regla pública
A24: PUB-023 | B24: F2 Sigma/Hayabusa histórico | C24: P3 Medium | D24: Windows.Hayabusa.Rules | E24: CLIENT / Hunt | F24: EVTX + Sigma/Hayabusa | G24: TEC-009 | H24: T1074.001 / T1560.001 | I24: Collection | J24: Evaluar detección histórica de staging/archivo | K24: Critical/High; luego Medium | L24: Regla sobre Compress-Archive / archive / staging si existe | M24: Pendiente | N24: Pendiente | O24: Pendiente | P24: Pendiente | Q24: Pendiente | R24: Pendiente | V24: Pendiente | W24: Sí | X24: No contar como exfiltración si no hay red externa
A25: PUB-024 | B25: F2 Sigma/Hayabusa tiempo real | C25: P3 Medium | D25: Windows.Hayabusa.Monitoring | E25: CLIENT_EVENT | F25: EVTX + Sigma/Hayabusa | G25: TEC-001 | H25: T1059.001 | I25: Execution | J25: Evaluar alerta HIDS pública en tiempo real para PowerShell | K25: Client Monitoring; Critical/High; luego Medium | L25: Evento de monitoring con RuleTitle, Level, EventID, ATT&CK | M25: Pendiente | N25: Pendiente | O25: Pendiente | P25: Pendiente | Q25: Pendiente | R25: Pendiente | V25: Pendiente | W25: Pendiente
